Workbook

Sheet Portada
C9: TRABAJO FINAL DE INGENIERÍA
C21: Alumno:
C22: Legajo:
C23: Docentes: Scali, Jorge
C24: Comisión:
C25: Localización:
C26: Email:

Sheet Indice
D2: Índice
D4: Hipótesis
D5: Proyección de ventas
D6: Modelo de ingresos
D7: Estructura de costos fijos
D8: Estructura de costos variables
D9: Estructura de costos de RRHH
D10: Modelo de egresos
D11: Modelo de inversión
D12: Amortizaciones
D13: Presupuesto Financiero
D14: Matriz de riesgos
... D18: Plan de contingencia

Sheet Hipótesis
E1: Hipótesis
B3: 1 - Descripción del negocio
B7: 2 - Mercado meta
B11: Clientes | C11: Gasto promedio (anual) | D11: Total mercado
B12: 427 | C12: 12000000 | D12: =B12*C12 -> 5124000000
B15: 3 - Participación del mercado
B16: participación del 10%
A22: Evolución de la participación en el mercado
A23: Año | B23: Cantidad | C23: Porcentaje | D23: Total
A24: 2026 | B24: 6 empresas medianas | C24: 0.02 | D24: =C24*$D$12 -> 102480000
A25: 2027 | B25: 15 empresas medianas | C25: 0.06 | D25: =C25*$D$12 -> 307440000
A26: 2028 | B26: 33 empresas medianas | C26: 0.1 | D26: =C26*$D$12 -> 512400000
B28: Detalle: Consideramos que una empresa mediana contrata unos 15 vehiculos promedio
B33: 4 - Otros datos
B35: Líneas de servicios
C36: AMPLITUD DE LA MEZCLA DE SERVICIOS
C39: Linea A | D39: Linea B
B40: PROFUNDIDAD DE LAS LÍNEAS DE SERVICIOS | C40: Instalación A | D40: Plan A
C43: Instalación B | D43: Plan B
C46: Instalación C | D46: Plan C
B56: Lista de precios por vehiculo
B57: Servicio | C57: Precio | D57: Detalle
B58: Instalación A | C58: 190000 | D58: Instalación de unidad central + sensor temperatura
B59: Instalación B | C59: 240000 | D59: Instalación sensor apertura puertas + bronce
B60: Instalación C | C60: 310000 | D60: Instalación gps, humedad y sensor motor + plata
B61: Plan A | C61: 88000 | D61: Monitoreo de temperatura | E61: Cobro mensual
B62: Plan B | C62: 108000 | D62: Incluye control de apertura de puertas + bronce | E62: Cobro mensual
B63: Plan C | C63: 132000 | D63: Incluye geolocalización, humedad y sensor de funcionamiento del motor + plata | E63: Cobro mensual

Sheet Proy. ventas
B1: Proyección de ventas
B5: Evolución de la participación | G5: Justificación ingresos
B6: 2026 | C6: 2027 | D6: 2028 | G6: En la proyección de ventas se podrá apreciar el efecto de la estacionalidad remarcada por las siguientes situaciones: a) Efecto temporada alta: Preveemos mayores ventas en los meses de septiembre, octubre y noviembre ya que las empresas de logística refrigerada se preparan para la temporada alta en el verano. Así mismo preveemos un incremento en las ventas en el mes de abril por esta misma causa. b) Estrategia de promoción: 30% de descuento en el precio de instalación para todos los planes durante los 3 años 30% de descuento en el mantenimiento del primer mes post-contratación durante el primer año y luego 100% bonificado el primer mes de mantenimiento.
B7: =Hipótesis!C24 -> 0.02 | C7: =Hipótesis!C25 -> 0.06 | D7: =Hipótesis!C26 -> 0.1
B8: =Hipótesis!D24 -> 102480000 | C8: =Hipótesis!D25 -> 307440000 | D8: =Hipótesis!D26 -> 512400000
A10: .
A15: Proyección de ventas 2026
A16: Producto | B16: Precio | C16: Anual | E16: Enero | G16: Febrero | I16: Marzo | K16: Abril | M16: Mayo | O16: Junio | Q16: Julio | S16: Agosto | U16: Septiembre | W16: Octubre | Y16: Noviembre | AA16: Diciembre
C17: Cantidad de vehiculos | D17: Ingresos | E17: =F32/$D$32 -> 0.060797799 | G17: =H32/$D$32 -> 0.056396149 | I17: =J32/$D$32 -> 0.030261348 | K17: =L32/$D$32 -> 0.078129298 | M17: =N32/$D$32 -> 0.045116919 | O17: =P32/$D$32 -> 0.045116919 | Q17: =R32/$D$32 -> 0.092984869 | S17: =T32/$D$32 -> 0.05997249 | U17: =V32/$D$32 -> 0.12077029 | W17: =X32/$D$32 -> 0.1389271 | Y17: =Z32/$D$32 -> 0.15708391 | AA17: =AB32/$D$32 -> 0.11444292
E18: Cantidad | F18: Ingresos | G18: Cantidad | H18: Ingresos | I18: Cantidad | J18: Ingresos | K18: Cantidad | L18: Ingresos | M18: Cantidad | N18: Ingresos | O18: Cantidad | P18: Ingresos | Q18: Cantidad | R18: Ingresos | S18: Cantidad | T18: Ingresos | U18: Cantidad | V18: Ingresos | W18: Cantidad | X18: Ingresos | Y18: Cantidad | Z18: Ingresos | AA18: Cantidad | AB18: Ingresos
A19: =Hipótesis!$B$58 -> Instalación A | B19: =Hipótesis!C58 -> 190000 | C19: =E19+G19+I19+K19+M19+O19+Q19+S19+U19+W19+Y19+AA19 -> 15 | D19: =B19*C19 -> 2850000 | E19: 0 | F19: =E19*$B$19 -> 0 | G19: 15 | H19: =G19*$B19 -> 2850000 | I19: 0 | J19: =I19*$B$19 -> 0 | K19: 0 | L19: =K19*$B$19 -> 0 | M19: 0 | N19: =M19*$B$19 -> 0 | O19: 0 | P19: =O19*$B$19 -> 0 | Q19: 0 | R19: =Q19*$B$19 -> 0 | S19: 0 | T19: =S19*$B$19 -> 0 | U19: 0 | V19: =U19*$B$19 -> 0 | W19: 0 | X19: =W19*$B$19 -> 0 | Y19: 0 | Z19: =Y19*$B$19 -> 0 | AA19: 0 | AB19: =AA19*$B$19 -> 0
A20: =Hipótesis!$B$59 -> Instalación B | B20: =Hipótesis!C59 -> 240000 | C20: =E20+G20+I20+K20+M20+O20+Q20+S20+U20+W20+Y20+AA20 -> 30 | D20: =B20*C20 -> 7200000 | E20: 0 | F20: =E20*$B$20 -> 0 | G20: 0 | H20: =G20*$B20 -> 0 | I20: 0 | J20: =I20*$B$20 -> 0 | K20: 15 | L20: =K20*$B$20 -> 3600000 | M20: 0 | N20: =M20*$B$20 -> 0 | O20: 0 | P20: =O20*$B$20 -> 0 | Q20: 15 | R20: =Q20*$B$20 -> 3600000 | S20: 0 | T20: =S20*$B$20 -> 0 | U20: 0 | V20: =U20*$B$20 -> 0 | W20: 0 | X20: =W20*$B$20 -> 0 | Y20: 0 | Z20: =Y20*$B$20 -> 0 | AA20: 0 | AB20: =AA20*$B$20 -> 0
A21: =Hipótesis!$B$60 -> Instalación C | B21: =Hipótesis!C60 -> 310000 | C21: =E21+G21+I21+K21+M21+O21+Q21+S21+U21+W21+Y21+AA21 -> 60 | D21: =B21*C21 -> 18600000 | E21: 15 | F21: =E21*$B$21 -> 4650000 | G21: 0 | H21: =G21*$B21 -> 0 | I21: 0 | J21: =I21*$B$21 -> 0 | K21: 0 | L21: =K21*$B$21 -> 0 | M21: 0 | N21: =M21*$B$21 -> 0 | O21: 0 | P21: =O21*$B$21 -> 0 | Q21: 0 | R21: =Q21*$B$21 -> 0 | S21: 0 | T21: =S21*$B$21 -> 0 | U21: 15 | V21: =U21*$B$21 -> 4650000 | W21: 15 | X21: =W21*$B$21 -> 4650000 | Y21: 15 | Z21: =Y21*$B$21 -> 4650000 | AA21: 0 | AB21: =AA21*$B$21 -> 0
A22: =Hipótesis!$B$61 -> Plan A | B22: =Hipótesis!C61 -> 88000 | C22: =E22+G22+I22+K22+M22+O22+Q22+S22+U22+W22+Y22+AA22 -> 165 | D22: =B22*C22 -> 14520000 | E22: =E19 -> 0 | F22: =E22*$B$22 -> 0 | G22: =E22+G19 -> 15 | H22: =G22*$B22 -> 1320000 | I22: =G22+I19 -> 15 | J22: =I22*$B$22 -> 1320000 | K22: =I22+K19 -> 15 | L22: =K22*$B$22 -> 1320000 | M22: =K22+M19 -> 15 | N22: =M22*$B$22 -> 1320000 | O22: =M22+O19 -> 15 | P22: =O22*$B$22 -> 1320000 | Q22: =O22+Q19 -> 15 | R22: =Q22*$B$22 -> 1320000 | S22: =Q22+S19 -> 15 | T22: =S22*$B$22 -> 1320000 | U22: =S22+U19 -> 15 | V22: =U22*$B$22 -> 1320000 | W22: =U22+W19 -> 15 | X22: =W22*$B$22 -> 1320000 | Y22: =W22+Y19 -> 15 | Z22: =Y22*$B$22 -> 1320000 | AA22: =Y22+AA19 -> 15 | AB22: =AA22*$B$22 -> 1320000
A23: =Hipótesis!$B$62 -> Plan B | B23: =Hipótesis!C62 -> 108000 | C23: =E23+G23+I23+K23+M23+O23+Q23+S23+U23+W23+Y23+AA23 -> 225 | D23: =B23*C23 -> 24300000 | E23: =E20 -> 0 | F23: =E23*$B$23 -> 0 | G23: =E23+G20 -> 0 | H23: =G23*$B23 -> 0 | I23: =G23+I20 -> 0 | J23: =I23*$B$23 -> 0 | K23: =I23+K20 -> 15 | L23: =K23*$B$23 -> 1620000 | M23: =K23+M20 -> 15 | N23: =M23*$B$23 -> 1620000 | O23: =M23+O20 -> 15 | P23: =O23*$B$23 -> 1620000 | Q23: =O23+Q20 -> 30 | R23: =Q23*$B$23 -> 3240000 | S23: =Q23+S20 -> 30 | T23: =S23*$B$23 -> 3240000 | U23: =S23+U20 -> 30 | V23: =U23*$B$23 -> 3240000 | W23: =U23+W20 -> 30 | X23: =W23*$B$23 -> 3240000 | Y23: =W23+Y20 -> 30 | Z23: =Y23*$B$23 -> 3240000 | AA23: =Y23+AA20 -> 30 | AB23: =AA23*$B$23 -> 3240000
A24: =Hipótesis!$B$63 -> Plan C | B24: =Hipótesis!C63 -> 132000 | C24: =E24+G24+I24+K24+M24+O24+Q24+S24+U24+W24+Y24+AA24 -> 315 | D24: =B24*C24 -> 41580000 | E24: =E21 -> 15 | F24: =E24*$B$24 -> 1980000 | G24: =E24+G21 -> 15 | H24: =G24*$B24 -> 1980000 | I24: =G24+I21 -> 15 | J24: =I24*$B$24 -> 1980000 | K24: =I24+K21 -> 15 | L24: =K24*$B$24 -> 1980000 | M24: =K24+M21 -> 15 | N24: =M24*$B$24 -> 1980000 | O24: =M24+O21 -> 15 | P24: =O24*$B$24 -> 1980000 | Q24: =O24+Q21 -> 15 | R24: =Q24*$B$24 -> 1980000 | S24: =Q24+S21 -> 15 | T24: =S24*$B$24 -> 1980000 | U24: =S24+U21 -> 30 | V24: =U24*$B$24 -> 3960000 | W24: =U24+W21 -> 45 | X24: =W24*$B$24 -> 5940000 | Y24: =W24+Y21 -> 60 | Z24: =Y24*$B$24 -> 7920000 | AA24: =Y24+AA21 -> 60 | AB24: =AA24*$B$24 -> 7920000
B25: =Hipótesis!C64 -> 0 | D25: =B25*C25 -> 0 | E25: 0 | F25: =E25*$B$25 -> 0 | G25: 0 | H25: =G25*$B25 -> 0 | I25: 0 | J25: =I25*$B$25 -> 0 | K25: 0 | L25: =K25*$B$25 -> 0 | M25: 0 | N25: =M25*$B$25 -> 0 | O25: 0 | P25: =O25*$B$25 -> 0 | Q25: 0 | R25: =Q25*$B$25 -> 0 | S25: 0 | T25: =S25*$B$25 -> 0 | U25: 0 | V25: =U25*$B$25 -> 0 | W25: 0 | X25: =W25*$B$25 -> 0 | Y25: 0 | Z25: =Y25*$B$25 -> 0 | AA25: 0 | AB25: =AA25*$B$25 -> 0
B26: =Hipótesis!C65 -> 0 | D26: =B26*C26 -> 0 | E26: 0 | F26: 0 | G26: 0 | H26: 0 | I26: 0 | J26: 0 | K26: 0 | L26: 0 | M26: 0 | N26: 0 | O26: 0 | P26: 0 | Q26: 0 | R26: 0 | S26: 0 | T26: 0 | U26: 0 | V26: 0 | W26: 0 | X26: 0 | Y26: 0 | Z26: 0 | AA26: 0 | AB26: 0
B27: =Hipótesis!C66 -> 0 | D27: =B27*C27 -> 0 | E27: 0 | F27: 0 | G27: 0 | H27: 0 | I27: 0 | J27: 0 | K27: 0 | L27: 0 | M27: 0 | N27: 0 | O27: 0 | P27: 0 | Q27: 0 | R27: 0 | S27: 0 | T27: 0 | U27: 0 | V27: 0 | W27: 0 | X27: 0 | Y27: 0 | Z27: 0 | AA27: 0 | AB27: 0
B28: =Hipótesis!C67 -> 0 | D28: =B28*C28 -> 0 | E28: 0 | F28: 0 | G28: 0 | H28: 0 | I28: 0 | J28: 0 | K28: 0 | L28: 0 | M28: 0 | N28: 0 | O28: 0 | P28: 0 | Q28: 0 | R28: 0 | S28: 0 | T28: 0 | U28: 0 | V28: 0 | W28: 0 | X28: 0 | Y28: 0 | Z28: 0 | AA28: 0 | AB28: 0
B29: =Hipótesis!C68 -> 0 | D29: =B29*C29 -> 0 | E29: 0 | F29: 0 | G29: 0 | H29: 0 | I29: 0 | J29: 0 | K29: 0 | L29: 0 | M29: 0 | N29: 0 | O29: 0 | P29: 0 | Q29: 0 | R29: 0 | S29: 0 | T29: 0 | U29: 0 | V29: 0 | W29: 0 | X29: 0 | Y29: 0 | Z29: 0 | AA29: 0 | AB29: 0
B30: =Hipótesis!C69 -> 0 | D30: =B30*C30 -> 0 | E30: 0 | F30: 0 | G30: 0 | H30: 0 | I30: 0 | J30: 0 | K30: 0 | L30: 0 | M30: 0 | N30: 0 | O30: 0 | P30: 0 | Q30: 0 | R30: 0 | S30: 0 | T30: 0 | U30: 0 | V30: 0 | W30: 0 | X30: 0 | Y30: 0 | Z30: 0 | AA30: 0 | AB30: 0
B31: =Hipótesis!C70 -> 0 | D31: =B31*C31 -> 0 | E31: 0 | F31: 0 | G31: 0 | H31: 0 | I31: 0 | J31: 0 | K31: 0 | L31: 0 | M31: 0 | N31: 0 | O31: 0 | P31: 0 | Q31: 0 | R31: 0 | S31: 0 | T31: 0 | U31: 0 | V31: 0 | W31: 0 | X31: 0 | Y31: 0 | Z31: 0 | AA31: 0 | AB31: 0
A32: Ingreso Total | D32: =SUM(D19:D31) -> 109050000 | F32: =SUM(F19:F31) -> 6630000 | H32: =SUM(H19:H31) -> 6150000 | J32: =SUM(J19:J31) -> 3300000 | L32: =SUM(L19:L31) -> 8520000 | N32: =SUM(N19:N31) -> 4920000 | P32: =SUM(P19:P31) -> 4920000 | R32: =SUM(R19:R31) -> 10140000 | T32: =SUM(T19:T31) -> 6540000 | V32: =SUM(V19:V31) -> 13170000 | X32: =SUM(X19:X31) -> 15150000 | Z32: =SUM(Z19:Z31) -> 17130000 | AB32: =SUM(AB19:AB31) -> 12480000
C33: =C19 -> 15 | E33: =E19 -> 0 | G33: =G19 -> 15 | I33: =I19 -> 0 | K33: =K19 -> 0 | M33: =M19 -> 0 | O33: =O19 -> 0 | Q33: =Q19 -> 0 | S33: =S19 -> 0 | U33: =U19 -> 0 | W33: =W19 -> 0 | Y33: =Y19 -> 0 | AA33: =AA19 -> 0
C34: =C20 -> 30 | E34: =E20 -> 0 | G34: =G20 -> 0 | I34: =I20 -> 0 | K34: =K20 -> 15 | M34: =M20 -> 0 | O34: =O20 -> 0 | Q34: =Q20 -> 15 | S34: =S20 -> 0 | U34: =U20 -> 0 | W34: =W20 -> 0 | Y34: =Y20 -> 0 | AA34: =AA20 -> 0
C35: =C21 -> 60 | E35: =E21 -> 15 | G35: =G21 -> 0 | I35: =I21 -> 0 | K35: =K21 -> 0 | M35: =M21 -> 0 | O35: =O21 -> 0 | Q35: =Q21 -> 0 | S35: =S21 -> 0 | U35: =U21 -> 15 | W35: =W21 -> 15 | Y35: =Y21 -> 15 | AA35: =AA21 -> 0
C36: =SUM(C22:C25) -> 705 | E36: =SUM(E22:E25) -> 15 | G36: =SUM(G22:G25) -> 30 | I36: =SUM(I22:I25) -> 30 | K36: =SUM(K22:K25) -> 45 | M36: =SUM(M22:M25) -> 45 | O36: =SUM(O22:O25) -> 45 | Q36: =SUM(Q22:Q25) -> 60 | S36: =SUM(S22:S25) -> 60 | U36: =SUM(U22:U25) -> 75 | W36: =SUM(W22:W25) -> 90 | Y36: =SUM(Y22:Y25) -> 105 | AA36: =SUM(AA22:AA25) -> 105
C37: =SUM(C26:C30) -> 0 | E37: =SUM(E26:E30) -> 0 | G37: =SUM(G26:G30) -> 0 | I37: =SUM(I26:I30) -> 0 | K37: =SUM(K26:K30) -> 0 | M37: =SUM(M26:M30) -> 0 | O37: =SUM(O26:O30) -> 0 | Q37: =SUM(Q26:Q30) -> 0 | S37: =SUM(S26:S30) -> 0 | U37: =SUM(U26:U30) -> 0 | W37: =SUM(W26:W30) -> 0 | Y37: =SUM(Y26:Y30) -> 0 | AA37: =SUM(AA26:AA30) -> 0
C38: =C31 -> 0 | E38: =E31 -> 0 | G38: =G31 -> 0 | I38: =I31 -> 0 | K38: =K31 -> 0 | M38: =M31 -> 0 | O38: =O31 -> 0 | Q38: =Q31 -> 0 | S38: =S31 -> 0 | U38: =U31 -> 0 | W38: =W31 -> 0 | Y38: =Y31 -> 0 | AA38: =AA31 -> 0
A40: Capacidad operativa Kick off - Año 2026
A41: Comentarios | B41: El emprendimiento saldrá al mercado habiendo invertido previamente en: * La plataforma digital, cuyo desarrollo fue realizado por los 2 socios fundadores, sumado a 2 desarrolladores jr tercerizados con una consultora. Será mantenido y ampliado por este equipo en una primera instancia. * Infraestructura: Oficina con sector de atención al público y depósito del hardware necesario para los clientes. * Capital de trabajo: se deberá contar con un stock inicial de sensores que irá incrementándose para cubrir las instalaciones de los nuevos clientes y posibles fallos que puedan suceder de clientes ya existentes. Además: * En Julio se contratará un encargado de soporte que trabajará de forma remota y rotando horarios con el anterior para cubrir una mayor franja horaria de soporte.
A42: Concepto | C42: Año cero - Kick off | E42: Año 2026
C43: Cantidad | E43: Enero | G43: Febrero | I43: Marzo | K43: Abril | M43: Mayo | O43: Junio | Q43: Julio | S43: Agosto | U43: Septiembre | W43: Octubre | Y43: Noviembre | AA43: Diciembre
A44: RRHH | C44: Gerente de administración | E44: Gerente de administración (+1) | G44: Sin cambios | I44: Sin cambios | K44: Sin cambios | M44: Sin cambios | O44: Sin cambios | Q44: Sin cambios | S44: Sin cambios | U44: Sin cambios | W44: Sin cambios | Y44: Sin cambios | AA44: Sin cambios
C45: Gerente de marketing | E45: Sin cambios | G45: Sin cambios | I45: Sin cambios | K45: Sin cambios | M45: Sin cambios | O45: Sin cambios | Q45: Sin cambios | S45: Sin cambios | U45: Sin cambios | W45: Sin cambios | Y45: Sin cambios | AA45: Sin cambios
C46: Gerente de sistemas | E46: Gerente de sistemas (+1) | G46: Sin cambios | I46: Sin cambios | K46: Sin cambios | M46: Sin cambios | O46: Sin cambios | Q46: Sin cambios | S46: Sin cambios | U46: Sin cambios | W46: Sin cambios | Y46: Sin cambios | AA46: Sin cambios
C47: Coordinador de soporte | E47: Sin cambios | G47: Sin cambios | I47: Sin cambios | K47: Sin cambios | M47: Sin cambios | O47: Sin cambios | Q47: Coordinador de soporte (+1) | S47: Sin cambios | U47: Sin cambios | W47: Sin cambios | Y47: Sin cambios | AA47: Sin cambios
C48: Soporte de nivel 1 | E48: Sin cambios | G48: Sin cambios | I48: Sin cambios | K48: Sin cambios | M48: Sin cambios | O48: Sin cambios | Q48: Sin cambios | S48: Sin cambios | U48: Sin cambios | W48: Sin cambios | Y48: Sin cambios | AA48: Sin cambios
C49: Auxiliar de ventas | E49: Sin cambios | G49: Sin cambios | I49: Sin cambios | K49: Sin cambios | M49: Sin cambios | O49: Sin cambios | Q49: Sin cambios | S49: Sin cambios | U49: Sin cambios | W49: Sin cambios | Y49: Sin cambios | AA49: Sin cambios
...

Sheet Anexo capacidad operativa
C1: Anexo capacidad operativa
A3: Instalación de sensores PuntoSens | H3: Mantenimiento plan | O3: Sueldo tecnico por hora: | P3: 12500 | S3: Coste instalación sensores | Y3: Coste mantenimiento sensores
A6: Cálculo de horas laborables de un empleado por mes
A7: Semanas por año | B7: 52 | C7: semanas
A8: Semanas de licencias varias al año | B8: 2 | C8: semanas
A9: Días festivos | B9: 14 | C9: días
A10: Días laborales totales | B10: =(B7-B8)*5 -B9 -> 236 | C10: días
A11: Jornada laboral | B11: 8 | C11: horas | T11: Instalación de unidad central + sensor temperatura
A12: Horas laborables anuales por empleado | B12: =B10*B11 -> 1888 | C12: horas | T12: Instalación sensor apertura puertas + bronce
A13: Consideraremos en promedio: | B13: 1800 | C13: Horas laborables anuales / empleado | T13: Instalación gps y sensor motor + plata
B14: 150 | C14: Horas laborables mensuales / empleado [HsLaboralesXMes]
A18: Instalación A | H18: Plan A | S18: Plan A | Y18: Mantenimiento plan A
A19: N° de tarea | B19: Descripción | C19: Base horaria [BH] | D19: Cantidad requerida [Cant] | E19: Horas por tarea Fórmula = Cant * BH | H19: N° de tarea | I19: Descripción | J19: Base horaria [BH] | K19: Cantidad requerida [Cant] | L19: Horas por tarea Fórmula = Cant * BH | S19: Componente | U19: Cantidad | V19: Precio unitario | W19: Subtotal | Y19: Componente | AA19: Cantidad | AB19: Precio unitario | AC19: Subtotal
A20: 1 | B20: Preparación | C20: 0.17 | D20: 1 | E20: =D20*C20 -> 0.17 | H20: 1 | I20: Revisión de sensores temp | J20: 0.1 | K20: 1 | L20: =K20*J20 -> 0.1 | S20: Unidad central | U20: 1 | V20: 30000 | W20: =V20*U20 -> 30000 | Y20: Servicio tecnico | AA20: =L32 -> 0.3 | AB20: =P3 -> 12500 | AC20: =AB20*AA20 -> 3750
A21: 2 | B21: Instalación sensores temperatura | C21: 0.42 | D21: 1 | E21: =D21*C21 -> 0.42 | H21: 2 | I21: Calibración remota | J21: 0.05 | K21: 1 | L21: =K21*J21 -> 0.05 | S21: Sensor temperatura | U21: 4 | V21: 12500 | W21: =V21*U21 -> 50000
A22: 3 | B22: Cableado/conexión | C22: 0.25 | D22: 1 | E22: =D22*C22 -> 0.25 | H22: 3 | I22: Monitoreo de alertas | J22: 0.1 | K22: 1 | L22: =K22*J22 -> 0.1 | S22: Instalación | U22: =E32 -> 1.01 | V22: =P3 -> 12500 | W22: =V22*U22 -> 12625 | AB22: =V3 -> 0
A23: 4 | B23: Calibración/pruebas | C23: 0.17 | D23: 1 | E23: =D23*C23 -> 0.17 | H23: 4 | I23: Reporte preventivo | J23: 0.05 | K23: 1 | L23: =K23*J23 -> 0.05
A24: 5 | E24: =D24*C24 -> 0 | H24: 5 | L24: =K24*J24 -> 0
A25: 6 | E25: =D25*C25 -> 0 | H25: 6
A26: 7 | E26: =D26*C26 -> 0 | H26: 7
A27: 8 | E27: =D27*C27 -> 0 | H27: 8
A28: 9 | E28: =D28*C28 -> 0 | H28: 9 | S28: Total | W28: =SUM(W20:W25) -> 92625 | Y28: Total | AC28: =SUM(AC20:AC25) -> 3750
A29: 10 | E29: =D29*C29 -> 0 | H29: 10
A30: 11 | E30: =D30*C30 -> 0 | H30: 11
A31: 12 | E31: =D31*C31 -> 0 | H31: 12
A32: Comentarios: | D32: Horas totales por servicio [HsTotalesXServicio] Fórmula = Σ Horas por tarea del servicio | E32: =SUM(E20:E31) -> 1.01 | F32: Coste por instalación | H32: Comentarios: | K32: Horas totales por servicio [HsTotalesXServicio] | L32: =SUM(L20:L31) -> 0.3
D33: Capacidad operativa mensual por proyecto Fórmula = HsTotalesXSer / HsLaboralesXMes | E33: =E32/$B$14 -> 0.0067333333 | F33: =$P$3*E32 -> 12625 | K33: Capacidad operativa mensual por proyecto | L33: =L32/$B$14 -> 0.002
A37: Instalación B | H37: Plan plata | S37: Plan B | Y37: Mantenimiento plan B
A38: N° de tarea | B38: Descripción | C38: Base horaria [BH] | D38: Cantidad requerida [Cant] | E38: Horas por tarea Fórmula = Cant * BH | H38: N° de tarea | I38: Descripción | J38: Base horaria [BH] | K38: Cantidad requerida [Cant] | L38: Horas por tarea Fórmula = Cant * BH | S38: Componente | U38: Cantidad | V38: Precio unitario | W38: Subtotal | Y38: Componente | AA38: Cantidad | AB38: Precio unitario | AC38: Subtotal
A39: 1 | B39: Preparación | C39: 0.25 | D39: 1 | E39: =D39*C39 -> 0.25 | H39: 1 | I39: Revision sensores temp | J39: 0.1 | K39: 1 | L39: =K39*J39 -> 0.1 | S39: Unidad central | U39: 1 | V39: 30000 | W39: =V39*U39 -> 30000 | Y39: Servicio tecnico | AA39: =L51 -> 0.6 | AB39: =P3 -> 12500 | AC39: =AB39*AA39 -> 7500
A40: 2 | B40: Instalación sensores temperatura | C40: 0.42 | D40: 1 | E40: =D40*C40 -> 0.42 | H40: 2 | I40: Revision sensores puertas | J40: 0.2 | K40: 1 | L40: =K40*J40 -> 0.2 | S40: Sensor temperatura | U40: 4 | V40: 12500 | W40: =V40*U40 -> 50000
A41: 3 | B41: Instalación sensores puertas | C41: 0.75 | D41: 1 | E41: =D41*C41 -> 0.75 | H41: 3 | I41: Calibración remota | J41: 0.1 | K41: 1 | L41: =K41*J41 -> 0.1 | S41: Sensor apertura puertas | U41: 1 | V41: 10000 | W41: =V41*U41 -> 10000
A42: 4 | B42: Cableado/conexión | C42: 0.33 | D42: 1 | E42: =D42*C42 -> 0.33 | H42: 4 | I42: Monitoreo de alertas | J42: 0.1 | K42: 1 | L42: =K42*J42 -> 0.1 | S42: Instalación | U42: =E51 -> 2 | V42: =P3 -> 12500 | W42: =V42*U42 -> 25000
A43: 5 | B43: Calibración/pruebas | C43: 0.25 | D43: 1 | E43: =D43*C43 -> 0.25 | H43: 5 | I43: Reporte preventivo | J43: 0.1 | K43: 1 | L43: =K43*J43 -> 0.1
A44: 6 | E44: =D44*C44 -> 0 | H44: 6 | L44: =K44*J44 -> 0
A45: 7 | E45: =D45*C45 -> 0 | H45: 7 | L45: 0
A46: 8 | E46: =D46*C46 -> 0 | H46: 8 | L46: 0
A47: 9 | E47: =D47*C47 -> 0 | H47: 9 | L47: 0 | S47: Total | W47: =SUM(W39:W44) -> 115000 | Y47: Total | AC47: =SUM(AC39:AC44) -> 7500
A48: 10 | E48: =D48*C48 -> 0 | H48: 10 | L48: 0
A49: 11 | E49: =D49*C49 -> 0 | H49: 11 | L49: 0
...

Sheet Mod. ingresos
E1: Modelo de ingresos
B7: Evolución de la participación
B8: 2026 | C8: 2027 | D8: 2028
B9: =Hipótesis!C24 -> 0.02 | C9: =Hipótesis!C25 -> 0.06 | D9: =Hipótesis!C26 -> 0.1
B10: =Hipótesis!D24 -> 102480000 | C10: =Hipótesis!D25 -> 307440000 | D10: =Hipótesis!D26 -> 512400000
B15: Ingresos por servicios
B16: Servicio | C16: Ingresos 2026 | D16: Ingresos 2027 | E16: Ingresos 2028
B17: =Hipótesis!$B$58 -> Instalación A | C17: ='Proy. ventas'!D19 -> 2850000 | D17: ='Proy. ventas'!D82 -> 5700000 | E17: ='Proy. ventas'!D144 -> 14250000
B18: =Hipótesis!$B$59 -> Instalación B | C18: ='Proy. ventas'!D20 -> 7200000 | D18: ='Proy. ventas'!D83 -> 3600000 | E18: ='Proy. ventas'!D145 -> 14400000
B19: =Hipótesis!$B$60 -> Instalación C | C19: ='Proy. ventas'!D21 -> 18600000 | D19: ='Proy. ventas'!D84 -> 27900000 | E19: ='Proy. ventas'!D146 -> 23250000
B20: =Hipótesis!$B$61 -> Plan A | C20: ='Proy. ventas'!D22 -> 14520000 | D20: ='Proy. ventas'!D85 -> 33000000 | E20: ='Proy. ventas'!D147 -> 104280000
B21: =Hipótesis!$B$62 -> Plan B | C21: ='Proy. ventas'!D23 -> 24300000 | D21: ='Proy. ventas'!D86 -> 55080000 | E21: ='Proy. ventas'!D148 -> 95580000
B22: =Hipótesis!$B$63 -> Plan C | C22: ='Proy. ventas'!D24 -> 41580000 | D22: ='Proy. ventas'!D87 -> 156420000 | E22: ='Proy. ventas'!D149 -> 285120000
C23: ='Proy. ventas'!D25 -> 0 | D23: ='Proy. ventas'!D88 -> 0 | E23: ='Proy. ventas'!D150 -> 0
C24: ='Proy. ventas'!D26 -> 0 | D24: ='Proy. ventas'!D89 -> 0 | E24: ='Proy. ventas'!D151 -> 0
C25: ='Proy. ventas'!D27 -> 0 | D25: ='Proy. ventas'!D90 -> 0 | E25: ='Proy. ventas'!D152 -> 0
C26: ='Proy. ventas'!D28 -> 0 | D26: ='Proy. ventas'!D91 -> 0 | E26: ='Proy. ventas'!D153 -> 0
C27: ='Proy. ventas'!D29 -> 0 | D27: ='Proy. ventas'!D92 -> 0 | E27: ='Proy. ventas'!D154 -> 0
C28: ='Proy. ventas'!D30 -> 0 | D28: ='Proy. ventas'!D93 -> 0 | E28: ='Proy. ventas'!D155 -> 0
C29: ='Proy. ventas'!D31 -> 0 | D29: ='Proy. ventas'!D94 -> 0 | E29: ='Proy. ventas'!D156 -> 0
B30: TOTALES | C30: =SUM(C17:C29) -> 109050000 | D30: =SUM(D17:D29) -> 281700000 | E30: =SUM(E17:E29) -> 536880000

Sheet Costos fijos
F1: Estructura de costos fijos
C3: Evolución de la participación | G3: Costos fijos - Totales
C4: 2026 | D4: 2027 | E4: 2028 | G4: 2026 | H4: 2027 | I4: 2028
C5: =Hipótesis!C24 -> 0.02 | D5: =Hipótesis!C25 -> 0.06 | E5: =Hipótesis!C26 -> 0.1 | G5: =P25 -> 26772000 | H5: =P42 -> 30638000 | I5: =P60 -> 37452000
C6: =Hipótesis!D24 -> 102480000 | D6: =Hipótesis!D25 -> 307440000 | E6: =Hipótesis!D26 -> 512400000
G7: Costos fijos promocion - Totales
G8: 2026 | H8: 2027 | I8: 2028
G9: =SUM(P23:P24) -> 1260000 | H9: =SUM(P40:P41) -> 1806000 | I9: =SUM(P58:P59) -> 2400000
B11: Costos fijos - Año 2026
B12: Conceptos | D12: Enero | E12: Febrero | F12: Marzo | G12: Abril | H12: Mayo | I12: Junio | J12: Julio | K12: Agosto | L12: Septiembre | M12: Octubre | N12: Noviembre | O12: Diciembre | P12: Total anual | Q12: Observaciones
B13: Servicios | C13: Luz | D13: 55000 | E13: 55000 | F13: 55000 | G13: 55000 | H13: 55000 | I13: 55000 | J13: 55000 | K13: 55000 | L13: 55000 | M13: 55000 | N13: 55000 | O13: 55000 | P13: =SUM(D13:O13) -> 660000
C14: Agua | D14: 19000 | E14: 19000 | F14: 19000 | G14: 19000 | H14: 19000 | I14: 19000 | J14: 19000 | K14: 19000 | L14: 19000 | M14: 19000 | N14: 19000 | O14: 19000 | P14: =SUM(D14:O14) -> 228000
C15: Telefonía móvil | D15: 0 | E15: 0 | F15: 0 | G15: 0 | H15: 0 | I15: 0 | J15: 0 | K15: 0 | L15: 0 | M15: 0 | N15: 0 | O15: 0 | P15: =SUM(D15:O15) -> 0
C16: Internet + Telefonía | D16: 40000 | E16: 40000 | F16: 40000 | G16: 40000 | H16: 40000 | I16: 40000 | J16: 40000 | K16: 40000 | L16: 40000 | M16: 40000 | N16: 40000 | O16: 40000 | P16: =SUM(D16:O16) -> 480000
C17: Infraestructura cloud | D17: 250000 | E17: 250000 | F17: 250000 | G17: 250000 | H17: 250000 | I17: 250000 | J17: 250000 | K17: 250000 | L17: 250000 | M17: 250000 | N17: 250000 | O17: 250000 | P17: =SUM(D17:O17) -> 3000000
C18: Impuesto municipal (Indicado en alquiler) | D18: 42000 | E18: 42000 | F18: 42000 | G18: 42000 | H18: 42000 | I18: 42000 | J18: 42000 | K18: 42000 | L18: 42000 | M18: 42000 | N18: 42000 | O18: 42000 | P18: =SUM(D18:O18) -> 504000
B19: Alquiler | C19: Oficina | D19: 1100000 | E19: 1100000 | F19: 1100000 | G19: 1100000 | H19: 1100000 | I19: 1100000 | J19: 1100000 | K19: 1100000 | L19: 1100000 | M19: 1100000 | N19: 1100000 | O19: 1100000 | P19: =SUM(D19:O19) -> 13200000 | Q19: En agosto, debido al crecimiento de empleados contratados, se adquiere una segunda oficina.
C20: Expensas (no posee) | D20: 0 | E20: 0 | F20: 0 | G20: 0 | H20: 0 | I20: 0 | J20: 0 | K20: 0 | L20: 0 | M20: 0 | N20: 0 | O20: 0 | P20: =SUM(D20:O20) -> 0
B21: Honorarios | C21: Estudio Contable | D21: 400000 | E21: 400000 | F21: 400000 | G21: 400000 | H21: 400000 | I21: 400000 | J21: 400000 | K21: 400000 | L21: 400000 | M21: 400000 | N21: 400000 | O21: 400000 | P21: =SUM(D21:O21) -> 4800000
C22: Consultora de RRHH - Liquidación sueldos y nuevas búsquedas | D22: 220000 | E22: 220000 | F22: 220000 | G22: 220000 | H22: 220000 | I22: 220000 | J22: 220000 | K22: 220000 | L22: 220000 | M22: 220000 | N22: 220000 | O22: 220000 | P22: =SUM(D22:O22) -> 2640000
B23: Publicidad online | C23: MetaAds | D23: 45000 | E23: 45000 | F23: 45000 | G23: 45000 | H23: 45000 | I23: 45000 | J23: 45000 | K23: 45000 | L23: 45000 | M23: 45000 | N23: 45000 | O23: 45000 | P23: =SUM(D23:O23) -> 540000
C24: GoogleAds | D24: 60000 | E24: 60000 | F24: 60000 | G24: 60000 | H24: 60000 | I24: 60000 | J24: 60000 | K24: 60000 | L24: 60000 | M24: 60000 | N24: 60000 | O24: 60000 | P24: =SUM(D24:O24) -> 720000
C25: Total | D25: =SUM(D13:D24) -> 2231000 | E25: =SUM(E13:E24) -> 2231000 | F25: =SUM(F13:F24) -> 2231000 | G25: =SUM(G13:G24) -> 2231000 | H25: =SUM(H13:H24) -> 2231000 | I25: =SUM(I13:I24) -> 2231000 | J25: =SUM(J13:J24) -> 2231000 | K25: =SUM(K13:K24) -> 2231000 | ... P25: =SUM(P13:P24) -> 26772000
B28: Costos fijos - Año 2027
B29: Conceptos | D29: Enero | E29: Febrero | F29: Marzo | G29: Abril | H29: Mayo | I29: Junio | J29: Julio | K29: Agosto | L29: Septiembre | M29: Octubre | N29: Noviembre | O29: Diciembre | P29: Total anual | Q29: Observaciones
B30: Servicios | C30: Luz | D30: 55000 | E30: 55000 | F30: 55000 | G30: 55000 | H30: 55000 | I30: 55000 | J30: 55000 | K30: 55000 | L30: 55000 | M30: 55000 | N30: 55000 | O30: 55000 | P30: =SUM(D30:O30) -> 660000
C31: Agua | D31: 19000 | E31: 19000 | F31: 19000 | G31: 19000 | H31: 19000 | I31: 19000 | J31: 19000 | K31: 19000 | L31: 19000 | M31: 19000 | N31: 19000 | O31: 19000 | P31: =SUM(D31:O31) -> 228000
C32: Telefonía móvil | D32: 0 | E32: 0 | F32: 20000 | G32: 20000 | H32: 20000 | I32: 20000 | J32: 20000 | K32: 20000 | L32: 20000 | M32: 20000 | N32: 20000 | O32: 20000 | P32: =SUM(D32:O32) -> 200000 | Q32: Debido a la incorporación de 2 recursos de Soporte técnico, se agregan 2 lineas más en Marzo y Julio.
C33: Internet + Telfonía | D33: 40000 | E33: 40000 | F33: 40000 | G33: 40000 | H33: 40000 | I33: 40000 | J33: 40000 | K33: 40000 | L33: 40000 | M33: 40000 | N33: 40000 | O33: 40000 | P33: =SUM(D33:O33) -> 480000
C34: Infraestructura cloud | D34: 300000 | E34: 300000 | F34: 300000 | G34: 300000 | H34: 300000 | I34: 300000 | J34: 300000 | K34: 300000 | L34: 300000 | M34: 300000 | N34: 300000 | O34: 300000 | P34: =SUM(D34:O34) -> 3600000
C35: Impuesto municipal (Indicado en alquiler) | D35: 42000 | E35: 42000 | F35: 42000 | G35: 42000 | H35: 42000 | I35: 42000 | J35: 42000 | K35: 42000 | L35: 42000 | M35: 42000 | N35: 42000 | O35: 42000 | P35: =SUM(D35:O35) -> 504000
B36: Alquiler | C36: Oficina | D36: 1100000 | E36: 1100000 | F36: 1100000 | G36: 1100000 | H36: 1100000 | I36: 1100000 | J36: 1100000 | K36: 1100000 | L36: 1100000 | M36: 1100000 | N36: 1100000 | O36: 1100000 | P36: =SUM(D36:O36) -> 13200000
C37: Expensas (no posee) | D37: 0 | E37: 0 | F37: 0 | G37: 0 | H37: 0 | I37: 0 | J37: 0 | K37: 0 | L37: 0 | M37: 0 | N37: 0 | O37: 0 | P37: =SUM(D37:O37) -> 0
B38: Honorarios | C38: Estudio Contable | D38: 500000 | E38: 500000 | F38: 500000 | G38: 500000 | H38: 500000 | I38: 500000 | J38: 500000 | K38: 500000 | L38: 500000 | M38: 500000 | N38: 500000 | O38: 500000 | P38: =SUM(D38:O38) -> 6000000
C39: Consultora de RRHH - Liquidación sueldos y nuevas búsquedas | D39: 330000 | E39: 330000 | F39: 330000 | G39: 330000 | H39: 330000 | I39: 330000 | J39: 330000 | K39: 330000 | L39: 330000 | M39: 330000 | N39: 330000 | O39: 330000 | P39: =SUM(D39:O39) -> 3960000
B40: Publicidad online | C40: MetaAds | D40: 65000 | E40: 65000 | F40: 65000 | G40: 65000 | H40: 65000 | I40: 65000 | J40: 65000 | K40: 65000 | L40: 65000 | M40: 65000 | N40: 65000 | O40: 65000 | P40: =SUM(D40:O40) -> 780000
C41: GoogleAds | D41: =950*60*1.5 -> 85500 | E41: =950*60*1.5 -> 85500 | F41: =950*60*1.5 -> 85500 | G41: =950*60*1.5 -> 85500 | H41: =950*60*1.5 -> 85500 | I41: =950*60*1.5 -> 85500 | J41: =950*60*1.5 -> 85500 | K41: =950*60*1.5 -> 85500 | ... O41: =950*60*1.5 -> 85500 | P41: =SUM(D41:O41) -> 1026000
C42: Total | D42: =SUM(D30:D41) -> 2536500 | E42: =SUM(E30:E41) -> 2536500 | F42: =SUM(F30:F41) -> 2556500 | G42: =SUM(G30:G41) -> 2556500 | H42: =SUM(H30:H41) -> 2556500 | I42: =SUM(I30:I41) -> 2556500 | J42: =SUM(J30:J41) -> 2556500 | K42: =SUM(K30:K41) -> 2556500 | ... P42: =SUM(P30:P41) -> 30638000
B46: Costos fijos - Año 2028
B47: Conceptos | D47: Enero | E47: Febrero | F47: Marzo | G47: Abril | H47: Mayo | I47: Junio | J47: Julio | K47: Agosto | L47: Septiembre | M47: Octubre | N47: Noviembre | O47: Diciembre | P47: Total anual | Q47: Observaciones
...

Sheet Costos variables
F1: Estructura de costos variables
B4: Evolución de la participación | H4: Costos variables - Totales
B5: 2026 | C5: 2027 | D5: 2028 | H5: 2026 | I5: 2027 | J5: 2028
B6: =Hipótesis!C24 -> 0.02 | C6: =Hipótesis!C25 -> 0.06 | D6: =Hipótesis!C26 -> 0.1 | H6: =AB32 -> 32918375 | I6: =AB55 -> 59495000 | J6: =AB78 -> 87758125
B7: =Hipótesis!D24 -> 102480000 | C7: =Hipótesis!D25 -> 307440000 | D7: =Hipótesis!D26 -> 512400000
H8: Costos de promoción - Totales
H9: 2026 | I9: 2027 | J9: 2028
H10: =SUM(AB21:AB29) -> 15599000 | I10: =SUM(AB44:AB52) -> 35240000 | J10: =SUM(AB67:AB75) -> 55930000
B12: Costos variables - Año 2026
B13: Concepto | D13: Enero | F13: Febrero | H13: Marzo | J13: Abril | L13: Mayo | N13: Junio | P13: Julio | R13: Agosto | T13: Septiembre | V13: Octubre | X13: Noviembre | Z13: Diciembre | AB13: Total
B14: Descripción | C14: Costo unitario | D14: Cantidad | E14: Costo | F14: Cantidad | G14: Costo | H14: Cantidad | I14: Costo | J14: Cantidad | K14: Costo | L14: Cantidad | M14: Costo | N14: Cantidad | O14: Costo | P14: Cantidad | Q14: Costo | R14: Cantidad | S14: Costo | T14: Cantidad | U14: Costo | V14: Cantidad | W14: Costo | X14: Cantidad | Y14: Costo | Z14: Cantidad | AA14: Costo
A15: Tipo de servicio | B15: ='Anexo capacidad operativa'!$S$18 -> Plan A | C15: ='Anexo capacidad operativa'!$W$28 -> 92625 | D15: ='Anexo capacidad operativa'!C80 -> 0 | E15: =D15*$C15 -> 0 | F15: ='Anexo capacidad operativa'!E80 -> 15 | G15: =F15*$C15 -> 1389375 | H15: ='Anexo capacidad operativa'!G80 -> 0 | I15: =H15*$C15 -> 0 | J15: ='Anexo capacidad operativa'!I80 -> 0 | K15: =J15*$C15 -> 0 | L15: ='Anexo capacidad operativa'!K80 -> 0 | M15: =L15*$C15 -> 0 | N15: ='Anexo capacidad operativa'!M80 -> 0 | O15: =N15*$C15 -> 0 | P15: ='Anexo capacidad operativa'!O80 -> 0 | Q15: =P15*$C15 -> 0 | R15: ='Anexo capacidad operativa'!Q80 -> 0 | S15: =R15*$C15 -> 0 | T15: ='Anexo capacidad operativa'!S80 -> 0 | U15: =T15*$C15 -> 0 | V15: ='Anexo capacidad operativa'!U80 -> 0 | W15: =V15*$C15 -> 0 | X15: ='Anexo capacidad operativa'!W80 -> 0 | Y15: =X15*$C15 -> 0 | Z15: ='Anexo capacidad operativa'!Y80 -> 0 | AA15: =Z15*$C15 -> 0 | AB15: =E15+G15+I15+K15+M15+O15+Q15+S15++U15+W15+Y15+AA15 -> 1389375
B16: ='Anexo capacidad operativa'!$S$37 -> Plan B | C16: ='Anexo capacidad operativa'!$W$47 -> 115000 | D16: ='Anexo capacidad operativa'!C81 -> 0 | E16: =D16*$C16 -> 0 | F16: ='Anexo capacidad operativa'!E81 -> 0 | G16: =F16*$C16 -> 0 | H16: ='Anexo capacidad operativa'!G81 -> 0 | I16: =H16*$C16 -> 0 | J16: ='Anexo capacidad operativa'!I81 -> 15 | K16: =J16*$C16 -> 1725000 | L16: ='Anexo capacidad operativa'!K81 -> 0 | M16: =L16*$C16 -> 0 | N16: ='Anexo capacidad operativa'!M81 -> 0 | O16: =N16*$C16 -> 0 | P16: ='Anexo capacidad operativa'!O81 -> 15 | Q16: =P16*$C16 -> 1725000 | R16: ='Anexo capacidad operativa'!Q81 -> 0 | S16: =R16*$C16 -> 0 | T16: ='Anexo capacidad operativa'!S81 -> 0 | U16: =T16*$C16 -> 0 | V16: ='Anexo capacidad operativa'!U81 -> 0 | W16: =V16*$C16 -> 0 | X16: ='Anexo capacidad operativa'!W81 -> 0 | Y16: =X16*$C16 -> 0 | Z16: ='Anexo capacidad operativa'!Y81 -> 0 | AA16: =Z16*$C16 -> 0 | AB16: =E16+G16+I16+K16+M16+O16+Q16+S16++U16+W16+Y16+AA16 -> 3450000
B17: ='Anexo capacidad operativa'!$S$56 -> Plan C | C17: ='Anexo capacidad operativa'!$W$65 -> 208000 | D17: ='Anexo capacidad operativa'!C82 -> 15 | E17: =D17*$C17 -> 3120000 | F17: ='Anexo capacidad operativa'!E82 -> 0 | G17: =F17*$C17 -> 0 | H17: ='Anexo capacidad operativa'!G82 -> 0 | I17: =H17*$C17 -> 0 | J17: ='Anexo capacidad operativa'!I82 -> 0 | K17: =J17*$C17 -> 0 | L17: ='Anexo capacidad operativa'!K82 -> 0 | M17: =L17*$C17 -> 0 | N17: ='Anexo capacidad operativa'!M82 -> 0 | O17: =N17*$C17 -> 0 | P17: ='Anexo capacidad operativa'!O82 -> 0 | Q17: =P17*$C17 -> 0 | R17: ='Anexo capacidad operativa'!Q82 -> 0 | S17: =R17*$C17 -> 0 | T17: ='Anexo capacidad operativa'!S82 -> 15 | U17: =T17*$C17 -> 3120000 | V17: ='Anexo capacidad operativa'!U82 -> 15 | W17: =V17*$C17 -> 3120000 | X17: ='Anexo capacidad operativa'!W82 -> 15 | Y17: =X17*$C17 -> 3120000 | Z17: ='Anexo capacidad operativa'!Y82 -> 0 | AA17: =Z17*$C17 -> 0 | AB17: =E17+G17+I17+K17+M17+O17+Q17+S17++U17+W17+Y17+AA17 -> 12480000
B18: ='Anexo capacidad operativa'!$Y$18 -> Mantenimiento plan A | C18: ='Anexo capacidad operativa'!$AC$28 -> 3750 | D18: ='Anexo capacidad operativa'!C83 -> 0 | E18: =D18*$C18 -> 0 | F18: ='Anexo capacidad operativa'!E83 -> 0 | G18: =F18*$C18 -> 0 | H18: ='Anexo capacidad operativa'!G83 -> 0 | I18: =H18*$C18 -> 0 | J18: ='Anexo capacidad operativa'!I83 -> 0 | K18: =J18*$C18 -> 0 | L18: ='Anexo capacidad operativa'!K83 -> 0 | M18: =L18*$C18 -> 0 | N18: ='Anexo capacidad operativa'!M83 -> 0 | O18: =N18*$C18 -> 0 | P18: ='Anexo capacidad operativa'!O83 -> 0 | Q18: =P18*$C18 -> 0 | R18: ='Anexo capacidad operativa'!Q83 -> 0 | S18: =R18*$C18 -> 0 | T18: ='Anexo capacidad operativa'!S83 -> 0 | U18: =T18*$C18 -> 0 | V18: ='Anexo capacidad operativa'!U83 -> 0 | W18: =V18*$C18 -> 0 | X18: ='Anexo capacidad operativa'!W83 -> 0 | Y18: =X18*$C18 -> 0 | Z18: ='Anexo capacidad operativa'!Y83 -> 0 | AA18: =Z18*$C18 -> 0 | AB18: =E18+G18+I18+K18+M18+O18+Q18+S18++U18+W18+Y18+AA18 -> 0
B19: ='Anexo capacidad operativa'!$Y$37 -> Mantenimiento plan B | C19: ='Anexo capacidad operativa'!$AC$47 -> 7500 | D19: ='Anexo capacidad operativa'!C84 -> 0 | E19: =D19*$C19 -> 0 | F19: ='Anexo capacidad operativa'!E84 -> 0 | G19: =F19*$C19 -> 0 | H19: ='Anexo capacidad operativa'!G84 -> 0 | I19: =H19*$C19 -> 0 | J19: ='Anexo capacidad operativa'!I84 -> 0 | K19: =J19*$C19 -> 0 | L19: ='Anexo capacidad operativa'!K84 -> 0 | M19: =L19*$C19 -> 0 | N19: ='Anexo capacidad operativa'!M84 -> 0 | O19: =N19*$C19 -> 0 | P19: ='Anexo capacidad operativa'!O84 -> 0 | Q19: =P19*$C19 -> 0 | R19: ='Anexo capacidad operativa'!Q84 -> 0 | S19: =R19*$C19 -> 0 | T19: ='Anexo capacidad operativa'!S84 -> 0 | U19: =T19*$C19 -> 0 | V19: ='Anexo capacidad operativa'!U84 -> 0 | W19: =V19*$C19 -> 0 | X19: ='Anexo capacidad operativa'!W84 -> 0 | Y19: =X19*$C19 -> 0 | Z19: ='Anexo capacidad operativa'!Y84 -> 0 | AA19: =Z19*$C19 -> 0 | AB19: =E19+G19+I19+K19+M19+O19+Q19+S19++U19+W19+Y19+AA19 -> 0
B20: ='Anexo capacidad operativa'!$Y$56 -> Mantenimiento plan C | C20: ='Anexo capacidad operativa'!$AC$65 -> 12500 | D20: ='Anexo capacidad operativa'!C85 -> 0 | E20: =D20*$C20 -> 0 | F20: ='Anexo capacidad operativa'!E85 -> 0 | G20: =F20*$C20 -> 0 | H20: ='Anexo capacidad operativa'!G85 -> 0 | I20: =H20*$C20 -> 0 | J20: ='Anexo capacidad operativa'!I85 -> 0 | K20: =J20*$C20 -> 0 | L20: ='Anexo capacidad operativa'!K85 -> 0 | M20: =L20*$C20 -> 0 | N20: ='Anexo capacidad operativa'!M85 -> 0 | O20: =N20*$C20 -> 0 | P20: ='Anexo capacidad operativa'!O85 -> 0 | Q20: =P20*$C20 -> 0 | R20: ='Anexo capacidad operativa'!Q85 -> 0 | S20: =R20*$C20 -> 0 | T20: ='Anexo capacidad operativa'!S85 -> 0 | U20: =T20*$C20 -> 0 | V20: ='Anexo capacidad operativa'!U85 -> 0 | W20: =V20*$C20 -> 0 | X20: ='Anexo capacidad operativa'!W85 -> 0 | Y20: =X20*$C20 -> 0 | Z20: ='Anexo capacidad operativa'!Y85 -> 0 | AA20: =Z20*$C20 -> 0 | AB20: =E20+G20+I20+K20+M20+O20+Q20+S20++U20+W20+Y20+AA20 -> 0
A21: Publicidad y promoción | B21: Ferias | C21: 300000 | D21: 0 | E21: =D21*$C21 -> 0 | F21: 0 | G21: =F21*$C21 -> 0 | H21: 1 | I21: =H21*$C21 -> 300000 | J21: 0 | K21: =J21*$C21 -> 0 | L21: 0 | M21: =L21*$C21 -> 0 | N21: 0 | O21: =N21*$C21 -> 0 | P21: 0 | Q21: =P21*$C21 -> 0 | R21: 0 | S21: =R21*$C21 -> 0 | T21: 0 | U21: =T21*$C21 -> 0 | V21: 0 | W21: =V21*$C21 -> 0 | X21: 0 | Y21: =X21*$C21 -> 0 | Z21: 0 | AA21: =Z21*$C21 -> 0 | AB21: =E21+G21+I21+K21+M21+O21+Q21+S21++U21+W21+Y21+AA21 -> 300000
B22: Carteleria | C22: 400000 | D22: 0 | E22: =D22*$C22 -> 0 | F22: 0 | G22: =F22*$C22 -> 0 | H22: 0 | I22: =H22*$C22 -> 0 | J22: 0 | K22: =J22*$C22 -> 0 | L22: 0 | M22: =L22*$C22 -> 0 | N22: 0 | O22: =N22*$C22 -> 0 | P22: 0 | Q22: =P22*$C22 -> 0 | R22: 1 | S22: =R22*$C22 -> 400000 | T22: 1 | U22: =T22*$C22 -> 400000 | V22: 1 | W22: =V22*$C22 -> 400000 | X22: 1 | Y22: =X22*$C22 -> 400000 | Z22: 1 | AA22: =Z22*$C22 -> 400000 | AB22: =E22+G22+I22+K22+M22+O22+Q22+S22++U22+W22+Y22+AA22 -> 2000000
B23: Radio | C23: 120000 | D23: 0 | E23: =D23*$C23 -> 0 | F23: 0 | G23: =F23*$C23 -> 0 | H23: 0 | I23: =H23*$C23 -> 0 | J23: 0 | K23: =J23*$C23 -> 0 | L23: 1 | M23: =L23*$C23 -> 120000 | N23: 1 | O23: =N23*$C23 -> 120000 | P23: 1 | Q23: =P23*$C23 -> 120000 | R23: 1 | S23: =R23*$C23 -> 120000 | T23: 1 | U23: =T23*$C23 -> 120000 | V23: 1 | W23: =V23*$C23 -> 120000 | X23: 1 | Y23: =X23*$C23 -> 120000 | Z23: 1 | AA23: =Z23*$C23 -> 120000 | AB23: =E23+G23+I23+K23+M23+O23+Q23+S23++U23+W23+Y23+AA23 -> 960000
B24: Bonificación de mantenimiento por contratación A | C24: =Hipótesis!$C$61*0.3 -> 26400 | D24: =D15 -> 0 | E24: =D24*$C24 -> 0 | F24: =F15 -> 15 | G24: =F24*$C24 -> 396000 | H24: =H15 -> 0 | I24: =H24*$C24 -> 0 | J24: =J15 -> 0 | K24: =J24*$C24 -> 0 | L24: =L15 -> 0 | M24: =L24*$C24 -> 0 | N24: =N15 -> 0 | O24: =N24*$C24 -> 0 | P24: =P15 -> 0 | Q24: =P24*$C24 -> 0 | R24: =R15 -> 0 | S24: =R24*$C24 -> 0 | T24: =T15 -> 0 | U24: =T24*$C24 -> 0 | V24: =V15 -> 0 | W24: =V24*$C24 -> 0 | X24: =X15 -> 0 | Y24: =X24*$C24 -> 0 | Z24: =Z15 -> 0 | AA24: =Z24*$C24 -> 0 | AB24: =E24+G24+I24+K24+M24+O24+Q24+S24++U24+W24+Y24+AA24 -> 396000
B25: Bonificación de mantenimiento por contratación B | C25: =Hipótesis!$C$62*0.3 -> 32400 | D25: =D16 -> 0 | E25: =D25*$C25 -> 0 | F25: =F16 -> 0 | G25: =F25*$C25 -> 0 | H25: =H16 -> 0 | I25: =H25*$C25 -> 0 | J25: =J16 -> 15 | K25: =J25*$C25 -> 486000 | L25: =L16 -> 0 | M25: =L25*$C25 -> 0 | N25: =N16 -> 0 | O25: =N25*$C25 -> 0 | P25: =P16 -> 15 | Q25: =P25*$C25 -> 486000 | R25: =R16 -> 0 | S25: =R25*$C25 -> 0 | T25: =T16 -> 0 | U25: =T25*$C25 -> 0 | V25: =V16 -> 0 | W25: =V25*$C25 -> 0 | X25: =X16 -> 0 | Y25: =X25*$C25 -> 0 | Z25: =Z16 -> 0 | AA25: =Z25*$C25 -> 0 | AB25: =E25+G25+I25+K25+M25+O25+Q25+S25++U25+W25+Y25+AA25 -> 972000
B26: Bonificación de mantenimiento por contratación C | C26: =Hipótesis!$C$63*0.3 -> 39600 | D26: =D17 -> 15 | E26: =D26*$C26 -> 594000 | F26: =F17 -> 0 | G26: =F26*$C26 -> 0 | H26: =H17 -> 0 | I26: =H26*$C26 -> 0 | J26: =J17 -> 0 | K26: =J26*$C26 -> 0 | L26: =L17 -> 0 | M26: =L26*$C26 -> 0 | N26: =N17 -> 0 | O26: =N26*$C26 -> 0 | P26: =P17 -> 0 | Q26: =P26*$C26 -> 0 | R26: =R17 -> 0 | S26: =R26*$C26 -> 0 | T26: =T17 -> 15 | U26: =T26*$C26 -> 594000 | V26: =V17 -> 15 | W26: =V26*$C26 -> 594000 | X26: =X17 -> 15 | Y26: =X26*$C26 -> 594000 | Z26: =Z17 -> 0 | AA26: =Z26*$C26 -> 0 | AB26: =E26+G26+I26+K26+M26+O26+Q26+S26++U26+W26+Y26+AA26 -> 2376000
B27: Bonificación de instalación por contratación A | C27: =Hipótesis!$C$58*0.3 -> 57000 | D27: =D15 -> 0 | E27: =D27*$C27 -> 0 | F27: =F15 -> 15 | G27: =F27*$C27 -> 855000 | H27: =H15 -> 0 | I27: =H27*$C27 -> 0 | J27: =J15 -> 0 | K27: =J27*$C27 -> 0 | L27: =L15 -> 0 | M27: =L27*$C27 -> 0 | N27: =N15 -> 0 | O27: =N27*$C27 -> 0 | P27: =P15 -> 0 | Q27: =P27*$C27 -> 0 | R27: =R15 -> 0 | S27: =R27*$C27 -> 0 | T27: =T15 -> 0 | U27: =T27*$C27 -> 0 | V27: =V15 -> 0 | W27: =V27*$C27 -> 0 | X27: =X15 -> 0 | Y27: =X27*$C27 -> 0 | Z27: =Z15 -> 0 | AA27: =Z27*$C27 -> 0 | AB27: =E27+G27+I27+K27+M27+O27+Q27+S27++U27+W27+Y27+AA27 -> 855000
B28: Bonificación de instalación por contratación B | C28: =Hipótesis!$C$59*0.3 -> 72000 | D28: =D16 -> 0 | E28: =D28*$C28 -> 0 | F28: =F16 -> 0 | G28: =F28*$C28 -> 0 | H28: =H16 -> 0 | I28: =H28*$C28 -> 0 | J28: =J16 -> 15 | K28: =J28*$C28 -> 1080000 | L28: =L16 -> 0 | M28: =L28*$C28 -> 0 | N28: =N16 -> 0 | O28: =N28*$C28 -> 0 | P28: =P16 -> 15 | Q28: =P28*$C28 -> 1080000 | R28: =R16 -> 0 | S28: =R28*$C28 -> 0 | T28: =T16 -> 0 | U28: =T28*$C28 -> 0 | V28: =V16 -> 0 | W28: =V28*$C28 -> 0 | X28: =X16 -> 0 | Y28: =X28*$C28 -> 0 | Z28: =Z16 -> 0 | AA28: =Z28*$C28 -> 0 | AB28: =E28+G28+I28+K28+M28+O28+Q28+S28++U28+W28+Y28+AA28 -> 2160000
B29: Bonificación de instalación por contratación C | C29: =Hipótesis!$C$60*0.3 -> 93000 | D29: =D17 -> 15 | E29: =D29*$C29 -> 1395000 | F29: =F17 -> 0 | G29: =F29*$C29 -> 0 | H29: =H17 -> 0 | I29: =H29*$C29 -> 0 | J29: =J17 -> 0 | K29: =J29*$C29 -> 0 | L29: =L17 -> 0 | M29: =L29*$C29 -> 0 | N29: =N17 -> 0 | O29: =N29*$C29 -> 0 | P29: =P17 -> 0 | Q29: =P29*$C29 -> 0 | R29: =R17 -> 0 | S29: =R29*$C29 -> 0 | T29: =T17 -> 15 | U29: =T29*$C29 -> 1395000 | V29: =V17 -> 15 | W29: =V29*$C29 -> 1395000 | X29: =X17 -> 15 | Y29: =X29*$C29 -> 1395000 | Z29: =Z17 -> 0 | AA29: =Z29*$C29 -> 0 | AB29: =E29+G29+I29+K29+M29+O29+Q29+S29++U29+W29+Y29+AA29 -> 5580000
C30: 0 | D30: 0 | E30: 0 | F30: 0 | G30: 0 | H30: 0 | I30: 0 | J30: 0 | K30: 0 | L30: 0 | M30: 0 | N30: 0 | O30: =($C$15*N15 + $C$16*N16+$C$17*N17)*0.15 -> 0 | P30: 0 | Q30: 0 | R30: 0 | S30: 0 | T30: 0 | U30: 0 | V30: 0 | W30: 0 | X30: 0 | Y30: 0 | Z30: 0 | AA30: 0 | AB30: =E30+G30+I30+K30+M30+O30+Q30+S30+U30+W30+Y30+AA30 -> 0
C31: 0 | D31: 0 | E31: 0 | F31: 0 | G31: 0 | H31: 0 | I31: =((H17*24)+(H16*18)+(H15*12))*6*1034 -> 0 | J31: 0 | K31: 0 | L31: 0 | M31: =((L17*24)+(L16*18)+(L15*12))*6*1034 -> 0 | N31: 0 | O31: =(N17+N16+N15)*75 -> 0 | P31: 0 | Q31: 0 | R31: 0 | S31: =((R17*24)+(R16*18)+(R15*12))*6*1034 -> 0 | T31: 0 | U31: 0 | V31: 0 | W31: 0 | X31: 0 | Y31: 0 | Z31: 0 | AA31: =((Z17*24)+(Z16*18)+(Z15*12))*6*1034 -> 0 | AB31: =E31+G31+I31+K31+M31+O31+Q31+S31+U31+W31+Y31+AA31 -> 0
B32: TOTAL | E32: =SUM(E15:E31) -> 5109000 | G32: =SUM(G15:G31) -> 2640375 | I32: =SUM(I15:I31) -> 300000 | K32: =SUM(K15:K31) -> 3291000 | M32: =SUM(M15:M31) -> 120000 | O32: =SUM(O15:O31) -> 120000 | Q32: =SUM(Q15:Q31) -> 3411000 | S32: =SUM(S15:S31) -> 520000 | U32: =SUM(U15:U31) -> 5629000 | W32: =SUM(W15:W31) -> 5629000 | Y32: =SUM(Y15:Y31) -> 5629000 | AA32: =SUM(AA15:AA31) -> 520000 | AB32: =SUM(E32:AA32) -> 32918375
B35: Costos variables - Año 2027
B36: Concepto | D36: Enero | F36: Febrero | H36: Marzo | J36: Abril | L36: Mayo | N36: Junio | P36: Julio | R36: Agosto | T36: Septiembre | V36: Octubre | X36: Noviembre | Z36: Diciembre | AB36: Total
B37: Descripción | C37: Costo unitario | D37: Cantidad | E37: Costo | F37: Cantidad | G37: Costo | H37: Cantidad | I37: Costo | J37: Cantidad | K37: Costo | L37: Cantidad | M37: Costo | N37: Cantidad | O37: Costo | P37: Cantidad | Q37: Costo | R37: Cantidad | S37: Costo | T37: Cantidad | U37: Costo | V37: Cantidad | W37: Costo | X37: Cantidad | Y37: Costo | Z37: Cantidad | AA37: Costo
A38: Tipo de servicio | B38: ='Anexo capacidad operativa'!$S$18 -> Plan A | C38: ='Anexo capacidad operativa'!$W$28 -> 92625 | D38: ='Anexo capacidad operativa'!C91 -> 0 | E38: =D38*$C38 -> 0 | F38: ='Anexo capacidad operativa'!E91 -> 0 | G38: =F38*$C38 -> 0 | H38: ='Anexo capacidad operativa'!G91 -> 0 | I38: =H38*$C38 -> 0 | J38: ='Anexo capacidad operativa'!I91 -> 15 | K38: =J38*$C38 -> 1389375 | L38: ='Anexo capacidad operativa'!K91 -> 0 | M38: =L38*$C38 -> 0 | N38: ='Anexo capacidad operativa'!M91 -> 0 | O38: =N38*$C38 -> 0 | P38: ='Anexo capacidad operativa'!O91 -> 0 | Q38: =P38*$C38 -> 0 | R38: ='Anexo capacidad operativa'!Q91 -> 0 | S38: =R38*$C38 -> 0 | T38: ='Anexo capacidad operativa'!S91 -> 15 | U38: =T38*$C38 -> 1389375 | V38: ='Anexo capacidad operativa'!U91 -> 0 | W38: =V38*$C38 -> 0 | X38: ='Anexo capacidad operativa'!W91 -> 0 | Y38: =X38*$C38 -> 0 | Z38: ='Anexo capacidad operativa'!Y91 -> 0 | AA38: =Z38*$C38 -> 0 | AB38: =E38+G38+I38+K38+M38+O38+Q38+S38++U38+W38+Y38+AA38 -> 2778750
B39: ='Anexo capacidad operativa'!$S$37 -> Plan B | C39: ='Anexo capacidad operativa'!$W$47 -> 115000 | D39: ='Anexo capacidad operativa'!C92 -> 0 | E39: =D39*$C39 -> 0 | F39: ='Anexo capacidad operativa'!E92 -> 0 | G39: =F39*$C39 -> 0 | H39: ='Anexo capacidad operativa'!G92 -> 15 | I39: =H39*$C39 -> 1725000 | J39: ='Anexo capacidad operativa'!I92 -> 0 | K39: =J39*$C39 -> 0 | L39: ='Anexo capacidad operativa'!K92 -> 0 | M39: =L39*$C39 -> 0 | N39: ='Anexo capacidad operativa'!M92 -> 0 | O39: =N39*$C39 -> 0 | P39: ='Anexo capacidad operativa'!O92 -> 0 | Q39: =P39*$C39 -> 0 | R39: ='Anexo capacidad operativa'!Q92 -> 0 | S39: =R39*$C39 -> 0 | T39: ='Anexo capacidad operativa'!S92 -> 0 | U39: =T39*$C39 -> 0 | V39: ='Anexo capacidad operativa'!U92 -> 0 | W39: =V39*$C39 -> 0 | X39: ='Anexo capacidad operativa'!W92 -> 0 | Y39: =X39*$C39 -> 0 | Z39: ='Anexo capacidad operativa'!Y92 -> 0 | AA39: =Z39*$C39 -> 0 | AB39: =E39+G39+I39+K39+M39+O39+Q39+S39++U39+W39+Y39+AA39 -> 1725000
B40: ='Anexo capacidad operativa'!$S$56 -> Plan C | C40: ='Anexo capacidad operativa'!$W$65 -> 208000 | D40: ='Anexo capacidad operativa'!C93 -> 15 | E40: =D40*$C40 -> 3120000 | F40: ='Anexo capacidad operativa'!E93 -> 0 | G40: =F40*$C40 -> 0 | H40: ='Anexo capacidad operativa'!G93 -> 0 | I40: =H40*$C40 -> 0 | J40: ='Anexo capacidad operativa'!I93 -> 15 | K40: =J40*$C40 -> 3120000 | L40: ='Anexo capacidad operativa'!K93 -> 0 | M40: =L40*$C40 -> 0 | N40: ='Anexo capacidad operativa'!M93 -> 0 | O40: =N40*$C40 -> 0 | P40: ='Anexo capacidad operativa'!O93 -> 0 | Q40: =P40*$C40 -> 0 | R40: ='Anexo capacidad operativa'!Q93 -> 0 | S40: =R40*$C40 -> 0 | T40: ='Anexo capacidad operativa'!S93 -> 0 | U40: =T40*$C40 -> 0 | V40: ='Anexo capacidad operativa'!U93 -> 30 | W40: =V40*$C40 -> 6240000 | X40: ='Anexo capacidad operativa'!W93 -> 30 | Y40: =X40*$C40 -> 6240000 | Z40: ='Anexo capacidad operativa'!Y93 -> 0 | AA40: =Z40*$C40 -> 0 | AB40: =E40+G40+I40+K40+M40+O40+Q40+S40++U40+W40+Y40+AA40 -> 18720000
B41: ='Anexo capacidad operativa'!$Y$18 -> Mantenimiento plan A | C41: ='Anexo capacidad operativa'!$AC$28 -> 3750 | D41: ='Anexo capacidad operativa'!C94 -> 0 | E41: =D41*$C41 -> 0 | F41: ='Anexo capacidad operativa'!E94 -> 15 | G41: =F41*$C41 -> 56250 | H41: ='Anexo capacidad operativa'!G94 -> 0 | I41: =H41*$C41 -> 0 | J41: ='Anexo capacidad operativa'!I94 -> 0 | K41: =J41*$C41 -> 0 | L41: ='Anexo capacidad operativa'!K94 -> 0 | M41: =L41*$C41 -> 0 | N41: ='Anexo capacidad operativa'!M94 -> 0 | O41: =N41*$C41 -> 0 | P41: ='Anexo capacidad operativa'!O94 -> 0 | Q41: =P41*$C41 -> 0 | R41: ='Anexo capacidad operativa'!Q94 -> 0 | S41: =R41*$C41 -> 0 | T41: ='Anexo capacidad operativa'!S94 -> 0 | U41: =T41*$C41 -> 0 | V41: ='Anexo capacidad operativa'!U94 -> 0 | W41: =V41*$C41 -> 0 | X41: ='Anexo capacidad operativa'!W94 -> 0 | Y41: =X41*$C41 -> 0 | Z41: ='Anexo capacidad operativa'!Y94 -> 0 | AA41: =Z41*$C41 -> 0 | AB41: =E41+G41+I41+K41+M41+O41+Q41+S41++U41+W41+Y41+AA41 -> 56250
B42: ='Anexo capacidad operativa'!$Y$37 -> Mantenimiento plan B | C42: ='Anexo capacidad operativa'!$AC$47 -> 7500 | D42: ='Anexo capacidad operativa'!C95 -> 0 | E42: =D42*$C42 -> 0 | F42: ='Anexo capacidad operativa'!E95 -> 0 | G42: =F42*$C42 -> 0 | H42: ='Anexo capacidad operativa'!G95 -> 0 | I42: =H42*$C42 -> 0 | J42: ='Anexo capacidad operativa'!I95 -> 15 | K42: =J42*$C42 -> 112500 | L42: ='Anexo capacidad operativa'!K95 -> 0 | M42: =L42*$C42 -> 0 | N42: ='Anexo capacidad operativa'!M95 -> 0 | O42: =N42*$C42 -> 0 | P42: ='Anexo capacidad operativa'!O95 -> 15 | Q42: =P42*$C42 -> 112500 | R42: ='Anexo capacidad operativa'!Q95 -> 0 | S42: =R42*$C42 -> 0 | T42: ='Anexo capacidad operativa'!S95 -> 0 | U42: =T42*$C42 -> 0 | V42: ='Anexo capacidad operativa'!U95 -> 0 | W42: =V42*$C42 -> 0 | X42: ='Anexo capacidad operativa'!W95 -> 0 | Y42: =X42*$C42 -> 0 | Z42: ='Anexo capacidad operativa'!Y95 -> 0 | AA42: =Z42*$C42 -> 0 | AB42: =E42+G42+I42+K42+M42+O42+Q42+S42++U42+W42+Y42+AA42 -> 225000
B43: ='Anexo capacidad operativa'!$Y$56 -> Mantenimiento plan C | C43: ='Anexo capacidad operativa'!$AC$65 -> 12500 | D43: ='Anexo capacidad operativa'!C96 -> 15 | E43: =D43*$C43 -> 187500 | F43: ='Anexo capacidad operativa'!E96 -> 0 | G43: =F43*$C43 -> 0 | H43: ='Anexo capacidad operativa'!G96 -> 0 | I43: =H43*$C43 -> 0 | J43: ='Anexo capacidad operativa'!I96 -> 0 | K43: =J43*$C43 -> 0 | L43: ='Anexo capacidad operativa'!K96 -> 0 | M43: =L43*$C43 -> 0 | N43: ='Anexo capacidad operativa'!M96 -> 0 | O43: =N43*$C43 -> 0 | P43: ='Anexo capacidad operativa'!O96 -> 0 | Q43: =P43*$C43 -> 0 | R43: ='Anexo capacidad operativa'!Q96 -> 0 | S43: =R43*$C43 -> 0 | T43: ='Anexo capacidad operativa'!S96 -> 15 | U43: =T43*$C43 -> 187500 | V43: ='Anexo capacidad operativa'!U96 -> 15 | W43: =V43*$C43 -> 187500 | X43: ='Anexo capacidad operativa'!W96 -> 15 | Y43: =X43*$C43 -> 187500 | Z43: ='Anexo capacidad operativa'!Y96 -> 0 | AA43: =Z43*$C43 -> 0 | AB43: =E43+G43+I43+K43+M43+O43+Q43+S43++U43+W43+Y43+AA43 -> 750000
A44: Publicidad y promoción | B44: Ferias | C44: 300000 | D44: 0 | E44: =D44*$C44 -> 0 | F44: 0 | G44: =F44*$C44 -> 0 | H44: 1 | I44: =H44*$C44 -> 300000 | J44: 0 | K44: =J44*$C44 -> 0 | L44: 0 | M44: =L44*$C44 -> 0 | N44: 0 | O44: =N44*$C44 -> 0 | P44: 0 | Q44: =P44*$C44 -> 0 | R44: 0 | S44: =R44*$C44 -> 0 | T44: 0 | U44: =T44*$C44 -> 0 | V44: 0 | W44: =V44*$C44 -> 0 | X44: 0 | Y44: =X44*$C44 -> 0 | Z44: 0 | AA44: =Z44*$C44 -> 0 | AB44: =E44+G44+I44+K44+M44+O44+Q44+S44++U44+W44+Y44+AA44 -> 300000
B45: Carteleria | C45: 400000 | D45: 1 | E45: =D45*$C45 -> 400000 | F45: 1 | G45: =F45*$C45 -> 400000 | H45: 1 | I45: =H45*$C45 -> 400000 | J45: 1 | K45: =J45*$C45 -> 400000 | L45: 1 | M45: =L45*$C45 -> 400000 | N45: 1 | O45: =N45*$C45 -> 400000 | P45: 1 | Q45: =P45*$C45 -> 400000 | R45: 1 | S45: =R45*$C45 -> 400000 | T45: 1 | U45: =T45*$C45 -> 400000 | V45: 1 | W45: =V45*$C45 -> 400000 | X45: 2 | Y45: =X45*$C45 -> 800000 | Z45: 2 | AA45: =Z45*$C45 -> 800000 | AB45: =E45+G45+I45+K45+M45+O45+Q45+S45++U45+W45+Y45+AA45 -> 5600000
...

Sheet Costos RRHH
E1: Estructura de costos de RRHH
B4: Evolución de la participación | H4: Costos de RRHH - Totales
B5: 2026 | C5: 2027 | D5: 2028 | H5: 2026 | I5: 2027 | J5: 2028
B6: =Hipótesis!C24 -> 0.02 | C6: =Hipótesis!C25 -> 0.06 | D6: =Hipótesis!C26 -> 0.1 | H6: =$AA$134 -> 77670014 | I6: =$AA$195 -> 1.4973145e+08 | J6: =$AA$256 -> 2.2191489e+08
B7: =Hipótesis!D24 -> 102480000 | C7: =Hipótesis!D25 -> 307440000 | D7: =Hipótesis!D26 -> 512400000
B9: Posición cubierta por otro puesto
B10: Posicion tercerizada
B13: Costo mensual por puesto
B14: Area | C14: Puesto | D14: Sueldo bruto | E14: Jubilación | F14: Ley 1932 | G14: Obra social | H14: F. Nac. Des. | I14: S. de Vida | J14: ART (Aprox.) | K14: Total aportes | L14: Costo mensual para empresa
E15: 0.1047 | F15: 0.0154 | G15: 0.06 | H15: 0.0092 | I15: $ 18,57 c/u | J15: 0.03
B16: Gerencia | C16: Gerente general | D16: 2400000 | E16: =$D$16*E15 -> 251280 | F16: =$D$16*F15 -> 36960 | G16: =$D$16*G15 -> 144000 | H16: =$D$16*H15 -> 22080 | I16: 18.57 | J16: =$D$16*J15 -> 72000 | K16: =SUM(E16:J16) -> 526338.57 | L16: =D16+K16 -> 2926338.6
B17: Administracion | C17: Gerente de administración | D17: 2000000 | E17: =$D17*$E$15 -> 209400 | F17: =$D17*F$15 -> 30800 | G17: =$D17*G$15 -> 120000 | H17: =$D17*H$15 -> 18400 | I17: 18.57 | J17: =$D17*J$15 -> 60000 | K17: =SUM(E17:J17) -> 438618.57 | L17: =D17+K17 -> 2438618.6
C18: Jefe de compras | D18: 1900000 | E18: =$D18*$E$15 -> 198930 | F18: =$D18*F$15 -> 29260 | G18: =$D18*G$15 -> 114000 | H18: =$D18*H$15 -> 17480 | I18: 18.57 | J18: =$D18*J$15 -> 57000 | K18: =SUM(E18:J18) -> 416688.57 | L18: =D18+K18 -> 2316688.6
C19: Jefe de finanzas | D19: 1900000 | E19: =$D19*$E$15 -> 198930 | F19: =$D19*F$15 -> 29260 | G19: =$D19*G$15 -> 114000 | H19: =$D19*H$15 -> 17480 | I19: 18.57 | J19: =$D19*J$15 -> 57000 | K19: =SUM(E19:J19) -> 416688.57 | L19: =D19+K19 -> 2316688.6
C20: Jefe de ventas | D20: 1900000 | E20: =$D20*$E$15 -> 198930 | F20: =$D20*F$15 -> 29260 | G20: =$D20*G$15 -> 114000 | H20: =$D20*H$15 -> 17480 | I20: 18.57 | J20: =$D20*J$15 -> 57000 | K20: =SUM(E20:J20) -> 416688.57 | L20: =D20+K20 -> 2316688.6
C21: Jefe de RRHH | D21: 1700000 | E21: =$D21*$E$15 -> 177990 | F21: =$D21*F$15 -> 26180 | G21: =$D21*G$15 -> 102000 | H21: =$D21*H$15 -> 15640 | I21: 18.57 | J21: =$D21*J$15 -> 51000 | K21: =SUM(E21:J21) -> 372828.57 | L21: =D21+K21 -> 2072828.6
C22: Subjefe de ventas | D22: 1600000 | E22: =$D22*$E$15 -> 167520 | F22: =$D22*F$15 -> 24640 | G22: =$D22*G$15 -> 96000 | H22: =$D22*H$15 -> 14720 | I22: 18.57 | J22: =$D22*J$15 -> 48000 | K22: =SUM(E22:J22) -> 350898.57 | L22: =D22+K22 -> 1950898.6
C23: Analista contable | D23: 1300000 | E23: =$D23*$E$15 -> 136110 | F23: =$D23*F$15 -> 20020 | G23: =$D23*G$15 -> 78000 | H23: =$D23*H$15 -> 11960 | I23: 18.57 | J23: =$D23*J$15 -> 39000 | K23: =SUM(E23:J23) -> 285108.57 | L23: =D23+K23 -> 1585108.6
C24: Analista de compras | D24: 1300000 | E24: =$D24*$E$15 -> 136110 | F24: =$D24*F$15 -> 20020 | G24: =$D24*G$15 -> 78000 | H24: =$D24*H$15 -> 11960 | I24: 18.57 | J24: =$D24*J$15 -> 39000 | K24: =SUM(E24:J24) -> 285108.57 | L24: =D24+K24 -> 1585108.6
C25: Administrativo de ventas | D25: 1200000 | E25: =$D25*$E$15 -> 125640 | F25: =$D25*F$15 -> 18480 | G25: =$D25*G$15 -> 72000 | H25: =$D25*H$15 -> 11040 | I25: 18.57 | J25: =$D25*J$15 -> 36000 | K25: =SUM(E25:J25) -> 263178.57 | L25: =D25+K25 -> 1463178.6
C26: Administrativo contable | D26: 1200000 | E26: =$D26*$E$15 -> 125640 | F26: =$D26*F$15 -> 18480 | G26: =$D26*G$15 -> 72000 | H26: =$D26*H$15 -> 11040 | I26: 18.57 | J26: =$D26*J$15 -> 36000 | K26: =SUM(E26:J26) -> 263178.57 | L26: =D26+K26 -> 1463178.6
C27: Administrativo de cobranzas | D27: 1200000 | E27: =$D27*$E$15 -> 125640 | F27: =$D27*F$15 -> 18480 | G27: =$D27*G$15 -> 72000 | H27: =$D27*H$15 -> 11040 | I27: 18.57 | J27: =$D27*J$15 -> 36000 | K27: =SUM(E27:J27) -> 263178.57 | L27: =D27+K27 -> 1463178.6
C28: Administrativo de compras | D28: 1100000 | E28: =$D28*$E$15 -> 115170 | F28: =$D28*F$15 -> 16940 | G28: =$D28*G$15 -> 66000 | H28: =$D28*H$15 -> 10120 | I28: 18.57 | J28: =$D28*J$15 -> 33000 | K28: =SUM(E28:J28) -> 241248.57 | L28: =D28+K28 -> 1341248.6
C29: Administrativo de pagos | D29: 1100000 | E29: =$D29*$E$15 -> 115170 | F29: =$D29*F$15 -> 16940 | G29: =$D29*G$15 -> 66000 | H29: =$D29*H$15 -> 10120 | I29: 18.57 | J29: =$D29*J$15 -> 33000 | K29: =SUM(E29:J29) -> 241248.57 | L29: =D29+K29 -> 1341248.6
... C31: Auxiliar administrativo | D31: 950000 | E31: =$D31*$E$15 -> 99465 | F31: =$D31*F$15 -> 14630 | G31: =$D31*G$15 -> 57000 | H31: =$D31*H$15 -> 8740 | I31: 18.57 | J31: =$D31*J$15 -> 28500 | K31: =SUM(E31:J31) -> 208353.57 | L31: =D31+K31 -> 1158353.6
B32: Marketing | C32: Gerente de marketing | D32: 2000000 | E32: =$D32*$E$15 -> 209400 | F32: =$D32*F$15 -> 30800 | G32: =$D32*G$15 -> 120000 | H32: =$D32*H$15 -> 18400 | I32: 18.57 | J32: =$D32*J$15 -> 60000 | K32: =SUM(E32:J32) -> 438618.57 | L32: =D32+K32 -> 2438618.6
C33: Lider de finanzas | D33: 2000000 | E33: =$D33*$E$15 -> 209400 | F33: =$D33*F$15 -> 30800 | G33: =$D33*G$15 -> 120000 | H33: =$D33*H$15 -> 18400 | I33: 18.57 | J33: =$D33*J$15 -> 60000 | K33: =SUM(E33:J33) -> 438618.57 | L33: =D33+K33 -> 2438618.6
C34: Lider de operaciones comerciales | D34: 1800000 | E34: =$D34*$E$15 -> 188460 | F34: =$D34*F$15 -> 27720 | G34: =$D34*G$15 -> 108000 | H34: =$D34*H$15 -> 16560 | I34: 18.57 | J34: =$D34*J$15 -> 54000 | K34: =SUM(E34:J34) -> 394758.57 | L34: =D34+K34 -> 2194758.6
C35: Coordinador de instalaciones | D35: 1500000 | E35: =$D35*$E$15 -> 157050 | F35: =$D35*F$15 -> 23100 | G35: =$D35*G$15 -> 90000 | H35: =$D35*H$15 -> 13800 | I35: 18.57 | J35: =$D35*J$15 -> 45000 | K35: =SUM(E35:J35) -> 328968.57 | L35: =D35+K35 -> 1828968.6
C36: Analista de producto | D36: 1500000 | E36: =$D36*$E$15 -> 157050 | F36: =$D36*F$15 -> 23100 | G36: =$D36*G$15 -> 90000 | H36: =$D36*H$15 -> 13800 | I36: 18.57 | J36: =$D36*J$15 -> 45000 | K36: =SUM(E36:J36) -> 328968.57 | L36: =D36+K36 -> 1828968.6
C37: Ejecutivo comercial | D37: 1500000 | E37: =$D37*$E$15 -> 157050 | F37: =$D37*F$15 -> 23100 | G37: =$D37*G$15 -> 90000 | H37: =$D37*H$15 -> 13800 | I37: 18.57 | J37: =$D37*J$15 -> 45000 | K37: =SUM(E37:J37) -> 328968.57 | L37: =D37+K37 -> 1828968.6
C38: Analista de logística | D38: 1300000 | E38: =$D38*$E$15 -> 136110 | F38: =$D38*F$15 -> 20020 | G38: =$D38*G$15 -> 78000 | H38: =$D38*H$15 -> 11960 | I38: 18.57 | J38: =$D38*J$15 -> 39000 | K38: =SUM(E38:J38) -> 285108.57 | L38: =D38+K38 -> 1585108.6
C39: Analista de marketing | D39: 1200000 | E39: =$D39*$E$15 -> 125640 | F39: =$D39*F$15 -> 18480 | G39: =$D39*G$15 -> 72000 | H39: =$D39*H$15 -> 11040 | I39: 18.57 | J39: =$D39*J$15 -> 36000 | K39: =SUM(E39:J39) -> 263178.57 | L39: =D39+K39 -> 1463178.6
C40: Diseñador de contenido | D40: 1200000 | E40: =$D40*$E$15 -> 125640 | F40: =$D40*F$15 -> 18480 | G40: =$D40*G$15 -> 72000 | H40: =$D40*H$15 -> 11040 | I40: 18.57 | J40: =$D40*J$15 -> 36000 | K40: =SUM(E40:J40) -> 263178.57 | L40: =D40+K40 -> 1463178.6
C41: Asistente de marketing | D41: 950000 | E41: =$D41*$E$15 -> 99465 | F41: =$D41*F$15 -> 14630 | G41: =$D41*G$15 -> 57000 | H41: =$D41*H$15 -> 8740 | I41: 18.57 | J41: =$D41*J$15 -> 28500 | K41: =SUM(E41:J41) -> 208353.57 | L41: =D41+K41 -> 1158353.6
B42: Tecnología | C42: Gerente de sistemas | D42: 2200000 | E42: =$D42*$E$15 -> 230340 | F42: =$D42*F$15 -> 33880 | G42: =$D42*G$15 -> 132000 | H42: =$D42*H$15 -> 20240 | I42: 18.57 | J42: =$D42*J$15 -> 66000 | K42: =SUM(E42:J42) -> 482478.57 | L42: =D42+K42 -> 2682478.6
C43: DevOps | D43: 2200000 | E43: =$D43*$E$15 -> 230340 | F43: =$D43*F$15 -> 33880 | G43: =$D43*G$15 -> 132000 | H43: =$D43*H$15 -> 20240 | I43: 18.57 | J43: =$D43*J$15 -> 66000 | K43: =SUM(E43:J43) -> 482478.57 | L43: =D43+K43 -> 2682478.6
C44: Arquitecto cloud | D44: 2100000 | E44: =$D44*$E$15 -> 219870 | F44: =$D44*F$15 -> 32340 | G44: =$D44*G$15 -> 126000 | H44: =$D44*H$15 -> 19320 | I44: 18.57 | J44: =$D44*J$15 -> 63000 | K44: =SUM(E44:J44) -> 460548.57 | L44: =D44+K44 -> 2560548.6
C45: Especialista en hardware | D45: 2000000 | E45: =$D45*$E$15 -> 209400 | F45: =$D45*F$15 -> 30800 | G45: =$D45*G$15 -> 120000 | H45: =$D45*H$15 -> 18400 | I45: 18.57 | J45: =$D45*J$15 -> 60000 | K45: =SUM(E45:J45) -> 438618.57 | L45: =D45+K45 -> 2438618.6
C46: Desarrollador backend SR | D46: 2100000 | E46: =$D46*$E$15 -> 219870 | F46: =$D46*F$15 -> 32340 | G46: =$D46*G$15 -> 126000 | H46: =$D46*H$15 -> 19320 | I46: 18.57 | J46: =$D46*J$15 -> 63000 | K46: =SUM(E46:J46) -> 460548.57 | L46: =D46+K46 -> 2560548.6
...

Sheet Mod. egresos
F1: Modelo de egresos
B3: Evolución de la participación
B4: 2026 | C4: 2027 | D4: 2028
