Workbook

Sheet Portada
C9: TRABAJO FINAL DE INGENIERÍA
C21: Alumno: Gómez Avellaneda, Javier
C22: Legajo: B00074234-T1
C23: Docentes: Scali, Jorge — Vilaboa, Pablo
C24: Comisión: 5° A - Turno Noche
C25: Localización: Sede Centro
C26: Email: javieralejandro.gomezavellaneda@alumnos.uai.edu.ar

Sheet Indice
D2: Índice
D4: Hipótesis
D5: Proyección de ventas
D6: Anexo de capacidad operativa
D7: Modelo de ingresos
D8: Estructura de costos fijos
D9: Estructura de costos variables
D10: Estructura de costos de RRHH
D11: Modelo de egresos
D12: Modelo de inversión
D13: Amortizaciones
D14: Presupuesto financiero
... D19: Plan de contingencia

Sheet Hipótesis
E1: Hipótesis
B3: 1 - Descripción del negocio
B4: ShopMetrics es una Empresa de Base Tecnológica (EBT) que desarrolla y explota software propio bajo modalidad SaaS para el comercio minorista. El negocio no consiste en la venta de dispositivos de conteo, sino en la provisión de un ecosistema de medición del embudo comercial del local: cuántas personas pasan por delante, cuántas se detienen frente a la vidriera, cuántas entran y cuántas compran. Los datos se capturan con infraestructura propia instalada en el local (sensores de vidriera y contadores de puerta que publican únicamente cantidades, nunca imágenes) y se integran de forma automática con el sistema de punto de venta que el comercio ya utiliza; sobre esa base, modelos propios de Machine Learning convierten la medición en decisiones de exhibición, dotación de personal y horario de atención. El servicio se contrata con un abono mensual y un cargo de alta e instalación por única vez, y los equipos se entregan en comodato, de modo que el comercio no afronta inversión inicial. Todos los importes de este presupuesto están expresados en dólares.
B7: 2 - Mercado meta
B8: Comercios minoristas con local a la calle y vidriera a la vereda, de entre uno y cinco locales y hasta nueve ocupados, ubicados en los ejes comerciales de mayor densidad del AMBA, que ya operan con alguno de los siete sistemas de punto de venta cubiertos por los conectores propios. El rubro de arranque es indumentaria, textiles y calzado
B9: Segmentación del mercado meta. El universo se segmenta por rubro sobre los 14.083 locales ocupados que el Instituto de Estadística y Censos de la Ciudad de Buenos Aires releva en los 53 ejes comerciales de mayor densidad (tercer cuatrimestre de 2025), redondeados a 14.000. Los tres segmentos comparten el mismo tramo de tamaño —de uno a cinco locales y hasta nueve ocupados— y por eso el gasto anual de referencia en herramientas de gestión, facturación electrónica y analítica es común, USD 960 por comercio; lo que los diferencia es la densidad de pares por eje y la prioridad comercial de ingreso. Segmento A — Indumentaria, textiles y calzado: compuesto por 3.400 comercios, el 24,3% de los locales ocupados relevados; es el rubro de mayor concentración del relevamiento y la cabecera de entrada por el eje Avellaneda, que reúne 1.073 locales con la ocupación más alta del operativo, 96,6%. Con un gasto anual de USD 960 por comercio consolida un mercado direccionable de USD 3.264.000. Segmento B — Alojamiento y comida: compuesto por 1.600 comercios, el 11,3% de los locales ocupados relevados; gastronomía con vidriera a la vereda, que comparte el mismo embudo de paso, detención e ingreso y la misma infraestructura de medición. Con un gasto anual de USD 960 por comercio consolida un mercado direccionable de USD 1.536.000. Segmento C — Resto de rubros con vidriera: compuesto por 9.000 comercios, el 64,4% de los locales ocupados relevados; alimentos y bebidas, perfumería, calzado deportivo y servicios con local a la calle, que comparten la infraestructura de medición con menor densidad de pares por rubro. Con un gasto anual de USD 960 por comercio consolida un mercado direccionable de USD 8.640.000. Total consolidado: los tres segmentos suman 14.000 comercios y un mercado direccionable de USD 13.440.000 anuales, que es el total que toma el cuadro siguiente. El universo del Gran Buenos Aires amplía esta cifra, pero no existe un operativo equivalente que lo mida con la misma fuente, de modo que queda fuera del dimensionamiento y dentro del plan de expansión.
B11: Comercios | C11: Gasto promedio anual (USD) | D11: Total mercado (USD)
B12: 14000 | C12: 960 | D12: =B12*C12 -> 13440000
B13: Los 14.000 comercios son los locales ocupados que el IDECBA releva en los 53 ejes comerciales de mayor densidad (tercer cuatrimestre de 2025). Todos tienen local a la calle y vidriera, que es la condición para instalar el servicio. El detalle por rubro y la ampliación al Gran Buenos Aires están en el punto 4 del informe.
B15: 3 - Participación del mercado
B16: Participación del 5,2% del universo al cierre del tercer año, con una progresión del 0,8% el primer año, 2,9% el segundo y 5,2% el tercero. Es una progresión moderada: el rubro de arranque concentra el esfuerzo comercial del primer año y la ampliación a los otros rubros con vidriera de los mismos ejes recién se aborda una vez validado ese rubro, de modo que el universo crece más rápido que la captación.
A22: Evolución de la participación en el mercado
A23: Año | B23: Cantidad | C23: Porcentaje | D23: Valor del mercado captado (USD) | E23: Facturación proyectada (USD)
A24: 2026 | B24: =SUBSTITUTE(TEXT('Proy. ventas'!AA36,"#,##0"),",",".")&" comercios" -> 271 comercios | C24: 0.008 | D24: =C24*$D$12 -> 107520 | E24: =SUM('Proy. ventas'!F32,'Proy. ventas'!H32,'Proy. ventas'!J32,'Proy. ventas'!L32,'Proy. ventas'!N32,'Proy. ventas'!P32,'Proy. ventas'!R32,'Proy. ventas'!T32,'Proy. ventas'!V32,'Proy. ventas'!X32,'Proy. ventas'!Z32,'Proy. ventas'!AB32) -> 105865
A25: 2027 | B25: =SUBSTITUTE(TEXT('Proy. ventas'!AA99,"#,##0"),",",".")&" comercios" -> 597 comercios | C25: 0.029 | D25: =C25*$D$12 -> 389760 | E25: =SUM('Proy. ventas'!F95,'Proy. ventas'!H95,'Proy. ventas'!J95,'Proy. ventas'!L95,'Proy. ventas'!N95,'Proy. ventas'!P95,'Proy. ventas'!R95,'Proy. ventas'!T95,'Proy. ventas'!V95,'Proy. ventas'!X95,'Proy. ventas'!Z95,'Proy. ventas'!AB95) -> 386897
A26: 2028 | B26: =SUBSTITUTE(TEXT('Proy. ventas'!AA161,"#,##0"),",",".")&" comercios" -> 1.033 comercios | C26: 0.052 | D26: =C26*$D$12 -> 698880 | E26: =SUM('Proy. ventas'!F157,'Proy. ventas'!H157,'Proy. ventas'!J157,'Proy. ventas'!L157,'Proy. ventas'!N157,'Proy. ventas'!P157,'Proy. ventas'!R157,'Proy. ventas'!T157,'Proy. ventas'!V157,'Proy. ventas'!X157,'Proy. ventas'!Z157,'Proy. ventas'!AB157) -> 705506
B29: El valor del mercado captado es el objetivo de facturación de cada año: participación por mercado total. La proyección de ventas se arma para alcanzarlo, y de ahí se obtiene la cantidad de comercios abonados que hace falta al cierre de cada año. La cantidad es mayor que la que resultaría de dividir el mercado captado por el gasto de referencia, porque el ticket promedio de la lista de precios es menor que ese gasto.
B31: Detalle: el gasto promedio anual de referencia son USD 960 (USD 80 mensuales), lo que un comercio minorista destina a software de gestión, facturación electrónica y analítica. Referencias 2026: planes de punto de venta con facturación electrónica y stock multi-tienda en el orden de USD 79 mensuales, y el plan de entrada de Fudo, uno de los sistemas con los que la plataforma se integra, en USD 40 mensuales por sucursal.
B33: 4 - Otros datos
B35: Líneas de servicios
C36: VERSIONES DEL SERVICIO
C39: Alta e instalación | D39: Abono mensual
B40: PROFUNDIDAD DE LAS LÍNEAS DE SERVICIOS | C40: Plan Básico | D40: Plan Básico
C43: Plan Vidriera | D43: Plan Vidriera
C46: Plan Cadena | D46: Plan Cadena
B56: Lista de precios (USD)
B57: Servicio | C57: Precio | D57: Detalle | E57: Modalidad de cobro
B58: Alta e instalación Plan Básico | C58: 40 | D58: Por única vez. Alta remota: conexión con el sistema de punto de venta y verificación de datos. No requiere visita al local. | E58: Cobro por única vez
B59: Alta e instalación Plan Vidriera | C59: 120 | D59: Por única vez. Visita al local: montaje del sensor de vidriera y del contador de puerta, conexión del punto de venta y prueba del embudo. | E59: Cobro por única vez
B60: Alta e instalación Plan Cadena | C60: 450 | D60: Por única vez. Instalación en hasta cinco locales de una misma cadena. | E60: Cobro por única vez
B61: Abono Plan Básico | C61: 33 | D61: Analítica de ventas por hora, ticket promedio y rotación, a partir del punto de venta. Sin dispositivos de conteo. Es la puerta de entrada comercial. | E61: Cobro mensual
B62: Abono Plan Vidriera | C62: 65 | D62: Embudo completo del local: pasan, se detienen, entran y compran, más comparación anónima contra el rubro y alertas automáticas. Es el plan principal. | E62: Cobro mensual
B63: Abono Plan Cadena | C63: 175 | D63: Hasta cinco locales: embudo por local, comparación entre sucursales y consolidado de toda la red. | E63: Cobro mensual

Sheet Proy. ventas
B1: Proyección de ventas
B5: Evolución de la participación | G5: Justificación ingresos
B6: 2026 | C6: 2027 | D6: 2028 | G6: La proyección se arma desde la facturación objetivo, que es el valor del mercado captado de la hoja Hipótesis (participación por mercado total: USD 105.754 en 2026, 385.805 en 2027 y 705.677 en 2028). Con la lista de precios fija, se calcula cuántas altas por mes hacen falta para llegar a ese número: el alta e instalación se cobra una sola vez y el abono es mensual y se acumula (el comercio que se da de alta en marzo sigue pagando en abril), de modo que el ingreso crece mes a mes aunque las altas sean parejas. El primer trimestre de 2026 tiene pocas altas porque se destina a los primeros comercios del eje Avellaneda; a partir de allí la captación crece de manera sostenida. Los porcentajes de cada mes son la proporción del total anual que se factura ese mes.
B7: =Hipótesis!C24 -> 0.008 | C7: =Hipótesis!C25 -> 0.029 | D7: =Hipótesis!C26 -> 0.052
B8: =Hipótesis!D24 -> 107520 | C8: =Hipótesis!D25 -> 389760 | D8: =Hipótesis!D26 -> 698880
A10: .
A15: Proyección de ventas 2026
A16: Producto | B16: Precio | C16: Anual | E16: Enero | G16: Febrero | I16: Marzo | K16: Abril | M16: Mayo | O16: Junio | Q16: Julio | S16: Agosto | U16: Septiembre | W16: Octubre | Y16: Noviembre | AA16: Diciembre
C17: Cantidad | D17: Ingresos | E17: =F32/$D$32 -> 0 | G17: =H32/$D$32 -> 0.0041845747 | I17: =J32/$D$32 -> 0.0074717801 | K17: =L32/$D$32 -> 0.019713786 | M17: =N32/$D$32 -> 0.033429368 | O17: =P32/$D$32 -> 0.053691022 | Q17: =R32/$D$32 -> 0.072545223 | S17: =T32/$D$32 -> 0.10082652 | U17: =V32/$D$32 -> 0.12412979 | W17: =X32/$D$32 -> 0.16080858 | Y17: =Z32/$D$32 -> 0.18925046 | AA17: =AB32/$D$32 -> 0.2339489
E18: Cantidad | F18: Ingresos | G18: Cantidad | H18: Ingresos | I18: Cantidad | J18: Ingresos | K18: Cantidad | L18: Ingresos | M18: Cantidad | N18: Ingresos | O18: Cantidad | P18: Ingresos | Q18: Cantidad | R18: Ingresos | S18: Cantidad | T18: Ingresos | U18: Cantidad | V18: Ingresos | W18: Cantidad | X18: Ingresos | Y18: Cantidad | Z18: Ingresos | AA18: Cantidad | AB18: Ingresos
A19: =Hipótesis!$B$58 -> Alta e instalación Plan Básico | B19: =Hipótesis!C58 -> 40 | C19: =E19+G19+I19+K19+M19+O19+Q19+S19+U19+W19+Y19+AA19 -> 74 | D19: =B19*C19 -> 2960 | E19: 0 | F19: =E19*$B$19 -> 0 | G19: 1 | H19: =G19*$B$19 -> 40 | I19: 1 | J19: =I19*$B$19 -> 40 | K19: 2 | L19: =K19*$B$19 -> 80 | M19: 4 | N19: =M19*$B$19 -> 160 | O19: 5 | P19: =O19*$B$19 -> 200 | Q19: 7 | R19: =Q19*$B$19 -> 280 | S19: 8 | T19: =S19*$B$19 -> 320 | U19: 9 | V19: =U19*$B$19 -> 360 | W19: 11 | X19: =W19*$B$19 -> 440 | Y19: 12 | Z19: =Y19*$B$19 -> 480 | AA19: 14 | AB19: =AA19*$B$19 -> 560
A20: =Hipótesis!$B$59 -> Alta e instalación Plan Vidriera | B20: =Hipótesis!C59 -> 120 | C20: =E20+G20+I20+K20+M20+O20+Q20+S20+U20+W20+Y20+AA20 -> 172 | D20: =B20*C20 -> 20640 | E20: 0 | F20: =E20*$B$20 -> 0 | G20: 2 | H20: =G20*$B$20 -> 240 | I20: 3 | J20: =I20*$B$20 -> 360 | K20: 5 | L20: =K20*$B$20 -> 600 | M20: 9 | N20: =M20*$B$20 -> 1080 | O20: 12 | P20: =O20*$B$20 -> 1440 | Q20: 15 | R20: =Q20*$B$20 -> 1800 | S20: 19 | T20: =S20*$B$20 -> 2280 | U20: 21 | V20: =U20*$B$20 -> 2520 | W20: 26 | X20: =W20*$B$20 -> 3120 | Y20: 27 | Z20: =Y20*$B$20 -> 3240 | AA20: 33 | AB20: =AA20*$B$20 -> 3960
A21: =Hipótesis!$B$60 -> Alta e instalación Plan Cadena | B21: =Hipótesis!C60 -> 450 | C21: =E21+G21+I21+K21+M21+O21+Q21+S21+U21+W21+Y21+AA21 -> 25 | D21: =B21*C21 -> 11250 | E21: 0 | F21: =E21*$B$21 -> 0 | G21: 0 | H21: =G21*$B$21 -> 0 | I21: 0 | J21: =I21*$B$21 -> 0 | K21: 1 | L21: =K21*$B$21 -> 450 | M21: 1 | N21: =M21*$B$21 -> 450 | O21: 2 | P21: =O21*$B$21 -> 900 | Q21: 2 | R21: =Q21*$B$21 -> 900 | S21: 3 | T21: =S21*$B$21 -> 1350 | U21: 3 | V21: =U21*$B$21 -> 1350 | W21: 4 | X21: =W21*$B$21 -> 1800 | Y21: 4 | Z21: =Y21*$B$21 -> 1800 | AA21: 5 | AB21: =AA21*$B$21 -> 2250
A22: =Hipótesis!$B$61 -> Abono Plan Básico | B22: =Hipótesis!C61 -> 33 | C22: =E22+G22+I22+K22+M22+O22+Q22+S22+U22+W22+Y22+AA22 -> 295 | D22: =B22*C22 -> 9735 | E22: =E19 -> 0 | F22: =E22*$B$22 -> 0 | G22: =E22+G19 -> 1 | H22: =G22*$B$22 -> 33 | I22: =G22+I19 -> 2 | J22: =I22*$B$22 -> 66 | K22: =I22+K19 -> 4 | L22: =K22*$B$22 -> 132 | M22: =K22+M19 -> 8 | N22: =M22*$B$22 -> 264 | O22: =M22+O19 -> 13 | P22: =O22*$B$22 -> 429 | Q22: =O22+Q19 -> 20 | R22: =Q22*$B$22 -> 660 | S22: =Q22+S19 -> 28 | T22: =S22*$B$22 -> 924 | U22: =S22+U19 -> 37 | V22: =U22*$B$22 -> 1221 | W22: =U22+W19 -> 48 | X22: =W22*$B$22 -> 1584 | Y22: =W22+Y19 -> 60 | Z22: =Y22*$B$22 -> 1980 | AA22: =Y22+AA19 -> 74 | AB22: =AA22*$B$22 -> 2442
A23: =Hipótesis!$B$62 -> Abono Plan Vidriera | B23: =Hipótesis!C62 -> 65 | C23: =E23+G23+I23+K23+M23+O23+Q23+S23+U23+W23+Y23+AA23 -> 687 | D23: =B23*C23 -> 44655 | E23: =E20 -> 0 | F23: =E23*$B$23 -> 0 | G23: =E23+G20 -> 2 | H23: =G23*$B$23 -> 130 | I23: =G23+I20 -> 5 | J23: =I23*$B$23 -> 325 | K23: =I23+K20 -> 10 | L23: =K23*$B$23 -> 650 | M23: =K23+M20 -> 19 | N23: =M23*$B$23 -> 1235 | O23: =M23+O20 -> 31 | P23: =O23*$B$23 -> 2015 | Q23: =O23+Q20 -> 46 | R23: =Q23*$B$23 -> 2990 | S23: =Q23+S20 -> 65 | T23: =S23*$B$23 -> 4225 | U23: =S23+U20 -> 86 | V23: =U23*$B$23 -> 5590 | W23: =U23+W20 -> 112 | X23: =W23*$B$23 -> 7280 | Y23: =W23+Y20 -> 139 | Z23: =Y23*$B$23 -> 9035 | AA23: =Y23+AA20 -> 172 | AB23: =AA23*$B$23 -> 11180
A24: =Hipótesis!$B$63 -> Abono Plan Cadena | B24: =Hipótesis!C63 -> 175 | C24: =E24+G24+I24+K24+M24+O24+Q24+S24+U24+W24+Y24+AA24 -> 95 | D24: =B24*C24 -> 16625 | E24: =E21 -> 0 | F24: =E24*$B$24 -> 0 | G24: =E24+G21 -> 0 | H24: =G24*$B$24 -> 0 | I24: =G24+I21 -> 0 | J24: =I24*$B$24 -> 0 | K24: =I24+K21 -> 1 | L24: =K24*$B$24 -> 175 | M24: =K24+M21 -> 2 | N24: =M24*$B$24 -> 350 | O24: =M24+O21 -> 4 | P24: =O24*$B$24 -> 700 | Q24: =O24+Q21 -> 6 | R24: =Q24*$B$24 -> 1050 | S24: =Q24+S21 -> 9 | T24: =S24*$B$24 -> 1575 | U24: =S24+U21 -> 12 | V24: =U24*$B$24 -> 2100 | W24: =U24+W21 -> 16 | X24: =W24*$B$24 -> 2800 | Y24: =W24+Y21 -> 20 | Z24: =Y24*$B$24 -> 3500 | AA24: =Y24+AA21 -> 25 | AB24: =AA24*$B$24 -> 4375
A32: Ingreso Total | D32: =SUM(D19:D31) -> 105865 | F32: =SUM(F19:F31) -> 0 | H32: =SUM(H19:H31) -> 443 | J32: =SUM(J19:J31) -> 791 | L32: =SUM(L19:L31) -> 2087 | N32: =SUM(N19:N31) -> 3539 | P32: =SUM(P19:P31) -> 5684 | R32: =SUM(R19:R31) -> 7680 | T32: =SUM(T19:T31) -> 10674 | V32: =SUM(V19:V31) -> 13141 | X32: =SUM(X19:X31) -> 17024 | Z32: =SUM(Z19:Z31) -> 20035 | AB32: =SUM(AB19:AB31) -> 24767
C33: =C19 -> 74 | E33: =E19 -> 0 | G33: =G19 -> 1 | I33: =I19 -> 1 | K33: =K19 -> 2 | M33: =M19 -> 4 | O33: =O19 -> 5 | Q33: =Q19 -> 7 | S33: =S19 -> 8 | U33: =U19 -> 9 | W33: =W19 -> 11 | Y33: =Y19 -> 12 | AA33: =AA19 -> 14
C34: =C20 -> 172 | E34: =E20 -> 0 | G34: =G20 -> 2 | I34: =I20 -> 3 | K34: =K20 -> 5 | M34: =M20 -> 9 | O34: =O20 -> 12 | Q34: =Q20 -> 15 | S34: =S20 -> 19 | U34: =U20 -> 21 | W34: =W20 -> 26 | Y34: =Y20 -> 27 | AA34: =AA20 -> 33
C35: =C21 -> 25 | E35: =E21 -> 0 | G35: =G21 -> 0 | I35: =I21 -> 0 | K35: =K21 -> 1 | M35: =M21 -> 1 | O35: =O21 -> 2 | Q35: =Q21 -> 2 | S35: =S21 -> 3 | U35: =U21 -> 3 | W35: =W21 -> 4 | Y35: =Y21 -> 4 | AA35: =AA21 -> 5
C36: =SUM(C22:C25) -> 1077 | E36: =SUM(E22:E25) -> 0 | G36: =SUM(G22:G25) -> 3 | I36: =SUM(I22:I25) -> 7 | K36: =SUM(K22:K25) -> 15 | M36: =SUM(M22:M25) -> 29 | O36: =SUM(O22:O25) -> 48 | Q36: =SUM(Q22:Q25) -> 72 | S36: =SUM(S22:S25) -> 102 | U36: =SUM(U22:U25) -> 135 | W36: =SUM(W22:W25) -> 176 | Y36: =SUM(Y22:Y25) -> 219 | AA36: =SUM(AA22:AA25) -> 271
C37: =SUM(C26:C30) -> 0 | E37: =SUM(E26:E30) -> 0 | G37: =SUM(G26:G30) -> 0 | I37: =SUM(I26:I30) -> 0 | K37: =SUM(K26:K30) -> 0 | M37: =SUM(M26:M30) -> 0 | O37: =SUM(O26:O30) -> 0 | Q37: =SUM(Q26:Q30) -> 0 | S37: =SUM(S26:S30) -> 0 | U37: =SUM(U26:U30) -> 0 | W37: =SUM(W26:W30) -> 0 | Y37: =SUM(Y26:Y30) -> 0 | AA37: =SUM(AA26:AA30) -> 0
C38: =C31 -> 0 | E38: =E31 -> 0 | G38: =G31 -> 0 | I38: =I31 -> 0 | K38: =K31 -> 0 | M38: =M31 -> 0 | O38: =O31 -> 0 | Q38: =Q31 -> 0 | S38: =S31 -> 0 | U38: =U31 -> 0 | W38: =W31 -> 0 | Y38: =Y31 -> 0 | AA38: =AA31 -> 0
A40: Capacidad operativa Kick off - Año 2026
A41: Comentarios | B41: * Se arranca sólo con los dos fundadores (gerencia general y gerencia de sistemas), que cubren entre ambos todos los puestos de la estructura. La instalación y el soporte se contratan por hora a técnicos freelance según las altas de cada mes, la venta se paga por comisión sobre cada alta y el desarrollo, la contabilidad y el marketing están tercerizados en los costos fijos.
A42: Concepto | C42: Año cero - Kick off | E42: Año 2026
C43: Cantidad | E43: Enero | G43: Febrero | I43: Marzo | K43: Abril | M43: Mayo | O43: Junio | Q43: Julio | S43: Agosto | U43: Septiembre | W43: Octubre | Y43: Noviembre | AA43: Diciembre
A44: RRHH | C44: Gerente general | E44: Sin cambios | G44: Sin cambios | I44: Sin cambios | K44: Sin cambios | M44: Sin cambios | O44: Sin cambios | Q44: Sin cambios | S44: Sin cambios | U44: Sin cambios | W44: Sin cambios | Y44: Sin cambios | AA44: Sin cambios
C45: Gerente de sistemas | E45: Sin cambios | G45: Sin cambios | I45: Sin cambios | K45: Sin cambios | M45: Sin cambios | O45: Sin cambios | Q45: Sin cambios | S45: Sin cambios | U45: Sin cambios | W45: Sin cambios | Y45: Sin cambios | AA45: Sin cambios
C46: Desarrollador | E46: Tercerizado (costo fijo) | G46: Sin cambios | I46: Sin cambios | K46: Sin cambios | M46: Sin cambios | O46: Sin cambios | Q46: Sin cambios | S46: Sin cambios | U46: Sin cambios | W46: Sin cambios | Y46: Sin cambios | AA46: Sin cambios
C47: Técnico de instalación y soporte | E47: Freelance por hora (costo variable) | G47: Sin cambios | I47: Sin cambios | K47: Sin cambios | M47: Sin cambios | O47: Sin cambios | Q47: Sin cambios | S47: Sin cambios | U47: Sin cambios | W47: Sin cambios | Y47: Sin cambios | AA47: Sin cambios
C48: Vendedor | E48: Comisión por alta (costo variable) | G48: Sin cambios | I48: Sin cambios | K48: Sin cambios | M48: Sin cambios | O48: Sin cambios | Q48: Sin cambios | S48: Sin cambios | U48: Sin cambios | W48: Sin cambios | Y48: Sin cambios | AA48: Sin cambios
A62: Infraestructura | C62: Oficina | E62: Oficina (+1 alquiler) | G62: Sin cambios | I62: Sin cambios | K62: Sin cambios | M62: Sin cambios | O62: Sin cambios | Q62: Sin cambios | S62: Sin cambios | U62: Sin cambios | W62: Sin cambios | Y62: Sin cambios | AA62: Sin cambios
C63: Notebooks | E63: Sin cambios | G63: Sin cambios | I63: Sin cambios | K63: Sin cambios | M63: Sin cambios | O63: Sin cambios | Q63: Sin cambios | S63: Sin cambios | U63: Sin cambios | W63: Sin cambios | Y63: Sin cambios | AA63: Sin cambios
C64: Escritorios | E64: Sin cambios | G64: Sin cambios | I64: Sin cambios | K64: Sin cambios | M64: Sin cambios | O64: Sin cambios | Q64: Sin cambios | S64: Sin cambios | U64: Sin cambios | W64: Sin cambios | Y64: Sin cambios | AA64: Sin cambios
C65: Sillas de escritorio | E65: Sin cambios | G65: Sin cambios | I65: Sin cambios | K65: Sin cambios | M65: Sin cambios | O65: Sin cambios | Q65: Sin cambios | S65: Sin cambios | U65: Sin cambios | W65: Sin cambios | Y65: Sin cambios | AA65: Sin cambios
C66: 0 | E66: Sin cambios | G66: Sin cambios | I66: Sin cambios | K66: Sin cambios | M66: Sin cambios | O66: Sin cambios | Q66: Sin cambios | S66: Sin cambios | U66: Sin cambios | W66: Sin cambios | Y66: Sin cambios | AA66: Sin cambios
C67: 0 | E67: Sin cambios | G67: Sin cambios | I67: Sin cambios | K67: Sin cambios | M67: Sin cambios | O67: Sin cambios | Q67: Sin cambios | S67: Sin cambios | U67: Sin cambios | W67: Sin cambios | Y67: Sin cambios | AA67: Sin cambios
C68: 0 | E68: Sin cambios | G68: Sin cambios | I68: Sin cambios | K68: Sin cambios | M68: Sin cambios | O68: Sin cambios | Q68: Sin cambios | S68: Sin cambios | U68: Sin cambios | W68: Sin cambios | Y68: Sin cambios | AA68: Sin cambios
A69: Capital de trabajo | C69: Sensores de vidriera | E69: Sensores de vidriera (+30) | G69: Sin cambios | I69: Sin cambios | K69: Sensores de vidriera (+30) | M69: Sin cambios | O69: Sin cambios | Q69: Sensores de vidriera (+30) | S69: Sin cambios | U69: Sin cambios | W69: Sensores de vidriera (+30) | Y69: Sin cambios | AA69: Sin cambios
...

Sheet Anexo capacidad operativa
C1: Anexo capacidad operativa
A3: Instalación y alta de los planes ShopMetrics | H3: Soporte mensual por plan | O3: Sueldo tecnico por hora: | P3: 6 | S3: Coste del kit de instalación | Y3: Coste del soporte mensual
A6: Cálculo de horas laborables de un empleado por mes
A7: Semanas por año | B7: 52 | C7: semanas
A8: Semanas de licencias varias al año | B8: 2 | C8: semanas
A9: Días festivos | B9: 14 | C9: días
A10: Días laborales totales | B10: =(B7-B8)*5 -B9 -> 236 | C10: días
A11: Jornada laboral | B11: 8 | C11: horas | T11: Alta remota: conexión con el punto de venta
A12: Horas laborables anuales por empleado | B12: =B10*B11 -> 1888 | C12: horas | T12: Visita al local: sensor de vidriera + contador de puerta
A13: Consideraremos en promedio: | B13: 1800 | C13: Horas laborables anuales / empleado | T13: Instalación en hasta cinco locales de una cadena
B14: 150 | C14: Horas laborables mensuales / empleado [HsLaboralesXMes]
A18: Alta e instalación Plan Básico | H18: Soporte mensual Plan Básico | S18: Kit Plan Básico | Y18: Soporte mensual Plan Básico
A19: N° de tarea | B19: Descripción | C19: Base horaria [BH] | D19: Cantidad requerida [Cant] | E19: Horas por tarea Fórmula = Cant * BH | H19: N° de tarea | I19: Descripción | J19: Base horaria [BH] | K19: Cantidad requerida [Cant] | L19: Horas por tarea Fórmula = Cant * BH | S19: Componente | U19: Cantidad | V19: Precio unitario | W19: Subtotal | Y19: Componente | AA19: Cantidad | AB19: Precio unitario | AC19: Subtotal
A20: 1 | B20: Contacto y coordinación | C20: 0.08 | D20: 1 | E20: =D20*C20 -> 0.08 | H20: 1 | I20: Monitoreo de ingesta | J20: 0.05 | K20: 1 | L20: =K20*J20 -> 0.05 | S20: Instalación (mano de obra) | U20: =$E$32 -> 0.5 | V20: =$P$3 -> 6 | W20: =V20*U20 -> 3 | Y20: Servicio técnico | AA20: =$L$32 -> 0.15 | AB20: =$P$3 -> 6 | AC20: =AB20*AA20 -> 0.9
A21: 2 | B21: Alta en la plataforma | C21: 0.08 | D21: 1 | E21: =D21*C21 -> 0.08 | H21: 2 | I21: Atención de consultas | J21: 0.07 | K21: 1 | L21: =K21*J21 -> 0.07
A22: 3 | B22: Conexión con el punto de venta | C22: 0.17 | D22: 1 | E22: =D22*C22 -> 0.17 | H22: 3 | I22: Reporte mensual | J22: 0.03 | K22: 1 | L22: =K22*J22 -> 0.03 | AB22: =V3 -> 0
A23: 4 | B23: Verificación de los datos | C23: 0.12 | D23: 1 | E23: =D23*C23 -> 0.12 | H23: 4 | L23: =K23*J23 -> 0
A24: 5 | B24: Capacitación remota | C24: 0.05 | D24: 1 | E24: =D24*C24 -> 0.05 | H24: 5 | L24: =K24*J24 -> 0
A25: 6 | E25: =D25*C25 -> 0 | H25: 6
A26: 7 | E26: =D26*C26 -> 0 | H26: 7
A27: 8 | E27: =D27*C27 -> 0 | H27: 8
A28: 9 | E28: =D28*C28 -> 0 | H28: 9 | S28: Total | W28: =SUM(W20:W25) -> 3 | Y28: Total | AC28: =SUM(AC20:AC25) -> 0.9
A29: 10 | E29: =D29*C29 -> 0 | H29: 10
A30: 11 | E30: =D30*C30 -> 0 | H30: 11
A31: 12 | E31: =D31*C31 -> 0 | H31: 12
A32: Comentarios: el alta del Plan Básico es remota, no requiere visita. | D32: Horas totales por servicio [HsTotalesXServicio] Fórmula = Σ Horas por tarea del servicio | E32: =SUM(E20:E31) -> 0.5 | F32: Coste por instalación | H32: Comentarios: soporte enteramente remoto. | K32: Horas totales por servicio [HsTotalesXServicio] | L32: =SUM(L20:L31) -> 0.15
D33: Capacidad operativa mensual por proyecto Fórmula = HsTotalesXSer / HsLaboralesXMes | E33: =E32/$B$14 -> 0.0033333333 | F33: =$P$3*E32 -> 3 | K33: Capacidad operativa mensual por proyecto | L33: =L32/$B$14 -> 0.001
A37: Alta e instalación Plan Vidriera | H37: Soporte mensual Plan Vidriera | S37: Kit Plan Vidriera | Y37: Soporte mensual Plan Vidriera
A38: N° de tarea | B38: Descripción | C38: Base horaria [BH] | D38: Cantidad requerida [Cant] | E38: Horas por tarea Fórmula = Cant * BH | H38: N° de tarea | I38: Descripción | J38: Base horaria [BH] | K38: Cantidad requerida [Cant] | L38: Horas por tarea Fórmula = Cant * BH | S38: Componente | U38: Cantidad | V38: Precio unitario | W38: Subtotal | Y38: Componente | AA38: Cantidad | AB38: Precio unitario | AC38: Subtotal
A39: 1 | B39: Coordinación y armado del kit | C39: 0.25 | D39: 1 | E39: =D39*C39 -> 0.25 | H39: 1 | I39: Monitoreo de ingesta | J39: 0.05 | K39: 1 | L39: =K39*J39 -> 0.05 | S39: Sensor de vidriera | U39: 1 | V39: 14 | W39: =V39*U39 -> 14 | Y39: Servicio técnico | AA39: =$L$51 -> 0.25 | AB39: =$P$3 -> 6 | AC39: =AB39*AA39 -> 1.5
A40: 2 | B40: Traslado al local | C40: 0.5 | D40: 1 | E40: =D40*C40 -> 0.5 | H40: 2 | I40: Control del sensor | J40: 0.07 | K40: 1 | L40: =K40*J40 -> 0.07 | S40: Contador de puerta | U40: 1 | V40: 9 | W40: =V40*U40 -> 9
A41: 3 | B41: Montaje del sensor de vidriera | C41: 0.75 | D41: 1 | E41: =D41*C41 -> 0.75 | H41: 3 | I41: Atención de consultas | J41: 0.08 | K41: 1 | L41: =K41*J41 -> 0.08 | S41: Gateway de conexión | U41: 1 | V41: 7 | W41: =V41*U41 -> 7
A42: 4 | B42: Instalación contador de puerta | C42: 0.5 | D42: 1 | E42: =D42*C42 -> 0.5 | H42: 4 | I42: Reporte mensual | J42: 0.05 | K42: 1 | L42: =K42*J42 -> 0.05 | S42: Kit de montaje | U42: 1 | V42: 4 | W42: =V42*U42 -> 4
A43: 5 | B43: Conexión con el punto de venta | C43: 0.25 | D43: 1 | E43: =D43*C43 -> 0.25 | H43: 5 | L43: =K43*J43 -> 0 | S43: Instalación (mano de obra) | U43: =$E$51 -> 3 | V43: =$P$3 -> 6 | W43: =V43*U43 -> 18
A44: 6 | B44: Prueba del embudo | C44: 0.5 | D44: 1 | E44: =D44*C44 -> 0.5 | H44: 6 | L44: =K44*J44 -> 0
A45: 7 | B45: Capacitación y cierre | C45: 0.25 | D45: 1 | E45: =D45*C45 -> 0.25 | H45: 7 | L45: 0
A46: 8 | E46: =D46*C46 -> 0 | H46: 8 | L46: 0
A47: 9 | E47: =D47*C47 -> 0 | H47: 9 | L47: 0 | S47: Total | W47: =SUM(W39:W44) -> 52 | Y47: Total | AC47: =SUM(AC39:AC44) -> 1.5
A48: 10 | E48: =D48*C48 -> 0 | H48: 10 | L48: 0
A49: 11 | E49: =D49*C49 -> 0 | H49: 11 | L49: 0
...

Sheet Mod. ingresos
E1: Modelo de ingresos
B7: Evolución de la participación
B8: 2026 | C8: 2027 | D8: 2028
B9: =Hipótesis!C24 -> 0.008 | C9: =Hipótesis!C25 -> 0.029 | D9: =Hipótesis!C26 -> 0.052
B10: =Hipótesis!D24 -> 107520 | C10: =Hipótesis!D25 -> 389760 | D10: =Hipótesis!D26 -> 698880
B15: Ingresos por servicios
B16: Servicio | C16: Ingresos 2026 | D16: Ingresos 2027 | E16: Ingresos 2028
B17: =Hipótesis!$B$58 -> Alta e instalación Plan Básico | C17: ='Proy. ventas'!D19 -> 2960 | D17: ='Proy. ventas'!D82 -> 3520 | E17: ='Proy. ventas'!D144 -> 4720
B18: =Hipótesis!$B$59 -> Alta e instalación Plan Vidriera | C18: ='Proy. ventas'!D20 -> 20640 | D18: ='Proy. ventas'!D83 -> 25200 | E18: ='Proy. ventas'!D145 -> 33360
B19: =Hipótesis!$B$60 -> Alta e instalación Plan Cadena | C19: ='Proy. ventas'!D21 -> 11250 | D19: ='Proy. ventas'!D84 -> 12600 | E19: ='Proy. ventas'!D146 -> 18000
B20: =Hipótesis!$B$61 -> Abono Plan Básico | C20: ='Proy. ventas'!D22 -> 9735 | D20: ='Proy. ventas'!D85 -> 46992 | E20: ='Proy. ventas'!D147 -> 87681
B21: =Hipótesis!$B$62 -> Abono Plan Vidriera | C21: ='Proy. ventas'!D23 -> 44655 | D21: ='Proy. ventas'!D86 -> 217035 | E21: ='Proy. ventas'!D148 -> 407745
B22: =Hipótesis!$B$63 -> Abono Plan Cadena | C22: ='Proy. ventas'!D24 -> 16625 | D22: ='Proy. ventas'!D87 -> 81550 | E22: ='Proy. ventas'!D149 -> 154000
B30: TOTALES | C30: =SUM(C17:C29) -> 105865 | D30: =SUM(D17:D29) -> 386897 | E30: =SUM(E17:E29) -> 705506

Sheet Costos fijos
F1: Estructura de costos fijos
C3: Evolución de la participación | G3: Costos fijos - Totales
C4: 2026 | D4: 2027 | E4: 2028 | G4: 2026 | H4: 2027 | I4: 2028
C5: =Hipótesis!C24 -> 0.008 | D5: =Hipótesis!C25 -> 0.029 | E5: =Hipótesis!C26 -> 0.052 | G5: =P26 -> 32640 | H5: =P44 -> 77700 | I5: =P63 -> 106860
C6: =Hipótesis!D24 -> 107520 | D6: =Hipótesis!D25 -> 389760 | E6: =Hipótesis!D26 -> 698880
G7: Costos fijos de promoción - Totales
G8: 2026 | H8: 2027 | I8: 2028
G9: =SUM(P23:P24) -> 2400 | H9: =SUM(P41:P42) -> 33240 | I9: =SUM(P60:P61) -> 52320
B11: Costos fijos - Año 2026
B12: Rubro | C12: Concepto | D12: Enero | E12: Febrero | F12: Marzo | G12: Abril | H12: Mayo | I12: Junio | J12: Julio | K12: Agosto | L12: Septiembre | M12: Octubre | N12: Noviembre | O12: Diciembre | P12: Total anual | Q12: Observaciones
B13: Servicios | C13: Luz | D13: 45 | E13: 45 | F13: 45 | G13: 45 | H13: 45 | I13: 45 | J13: 45 | K13: 45 | L13: 45 | M13: 45 | N13: 45 | O13: 45 | P13: =SUM(D13:O13) -> 540
C14: Agua | D14: 15 | E14: 15 | F14: 15 | G14: 15 | H14: 15 | I14: 15 | J14: 15 | K14: 15 | L14: 15 | M14: 15 | N14: 15 | O14: 15 | P14: =SUM(D14:O14) -> 180
C15: Internet y telefonía fija | D15: 60 | E15: 60 | F15: 60 | G15: 60 | H15: 60 | I15: 60 | J15: 60 | K15: 60 | L15: 60 | M15: 60 | N15: 60 | O15: 60 | P15: =SUM(D15:O15) -> 720
C16: Telefonía móvil | D16: 30 | E16: 30 | F16: 30 | G16: 30 | H16: 30 | I16: 30 | J16: 30 | K16: 30 | L16: 30 | M16: 30 | N16: 30 | O16: 30 | P16: =SUM(D16:O16) -> 360 | Q16: Una línea por técnico y por vendedor; escala con la dotación.
C17: Infraestructura cloud base | D17: 250 | E17: 250 | F17: 250 | G17: 250 | H17: 250 | I17: 250 | J17: 250 | K17: 250 | L17: 250 | M17: 250 | N17: 250 | O17: 250 | P17: =SUM(D17:O17) -> 3000 | Q17: Capacidad mínima para operar con independencia de la cantidad de comercios activos.
C18: Licencias de software | D18: 120 | E18: 120 | F18: 120 | G18: 120 | H18: 120 | I18: 120 | J18: 120 | K18: 120 | L18: 120 | M18: 120 | N18: 120 | O18: 120 | P18: =SUM(D18:O18) -> 1440 | Q18: Herramientas de desarrollo, monitoreo y productividad.
B19: Alquiler | C19: Oficina | D19: 600 | E19: 600 | F19: 600 | G19: 600 | H19: 600 | I19: 600 | J19: 600 | K19: 600 | L19: 600 | M19: 600 | N19: 600 | O19: 600 | P19: =SUM(D19:O19) -> 7200 | Q19: En 2028 se amplía el espacio por el crecimiento de la dotación.
C20: Auditoría y certificación ISO 27001 | D20: 0 | E20: 0 | F20: 0 | G20: 0 | H20: 0 | I20: 0 | J20: 0 | K20: 0 | L20: 0 | M20: 0 | N20: 0 | O20: 0 | P20: =SUM(D20:O20) -> 0 | Q20: Implementación durante 2027 y mantenimiento desde 2028.
B21: Honorarios | C21: Estudio Contable Externo | D21: 400 | E21: 400 | F21: 400 | G21: 400 | H21: 400 | I21: 400 | J21: 400 | K21: 400 | L21: 400 | M21: 400 | N21: 400 | O21: 400 | P21: =SUM(D21:O21) -> 4800 | Q21: Escala por tramos con la cantidad de empleados.
C22: Agencia de marketing | D22: 400 | E22: 400 | F22: 400 | G22: 400 | H22: 400 | I22: 400 | J22: 400 | K22: 400 | L22: 400 | M22: 400 | N22: 400 | O22: 400 | P22: =SUM(D22:O22) -> 4800 | Q22: Abono mensual; la pauta se imputa aparte.
B23: Publicidad online | C23: Campañas base en Meta y Google | D23: 150 | E23: 150 | F23: 150 | G23: 150 | H23: 150 | I23: 150 | J23: 150 | K23: 150 | L23: 150 | M23: 150 | N23: 150 | O23: 150 | P23: =SUM(D23:O23) -> 1800 | Q23: Pauta base permanente; las campañas de captación intensiva van en costos variables.
C24: Sitio web, SEO local y WhatsApp Business | D24: 50 | E24: 50 | F24: 50 | G24: 50 | H24: 50 | I24: 50 | J24: 50 | K24: 50 | L24: 50 | M24: 50 | N24: 50 | O24: 50 | P24: =SUM(D24:O24) -> 600
C25: Desarrollo y mantenimiento tercerizado | D25: 600 | E25: 600 | F25: 600 | G25: 600 | H25: 600 | I25: 600 | J25: 600 | K25: 600 | L25: 600 | M25: 600 | N25: 600 | O25: 600 | P25: =SUM(D25:O25) -> 7200 | Q25: Free lance, 20/40/60 h por mes según el año. Sin cargas patronales.
B26: TOTAL | D26: =SUM(D13:D25) -> 2720 | E26: =SUM(E13:E25) -> 2720 | F26: =SUM(F13:F25) -> 2720 | G26: =SUM(G13:G25) -> 2720 | H26: =SUM(H13:H25) -> 2720 | I26: =SUM(I13:I25) -> 2720 | J26: =SUM(J13:J25) -> 2720 | K26: =SUM(K13:K25) -> 2720 | ... O26: =SUM(O13:O25) -> 2720 | P26: =SUM(D26:O26) -> 32640
B29: Costos fijos - Año 2027
B30: Rubro | C30: Concepto | D30: Enero | E30: Febrero | F30: Marzo | G30: Abril | H30: Mayo | I30: Junio | J30: Julio | K30: Agosto | L30: Septiembre | M30: Octubre | N30: Noviembre | O30: Diciembre | P30: Total anual | Q30: Observaciones
B31: Servicios | C31: Luz | D31: 45 | E31: 45 | F31: 45 | G31: 45 | H31: 45 | I31: 45 | J31: 45 | K31: 45 | L31: 45 | M31: 45 | N31: 45 | O31: 45 | P31: =SUM(D31:O31) -> 540
C32: Agua | D32: 15 | E32: 15 | F32: 15 | G32: 15 | H32: 15 | I32: 15 | J32: 15 | K32: 15 | L32: 15 | M32: 15 | N32: 15 | O32: 15 | P32: =SUM(D32:O32) -> 180
C33: Internet y telefonía fija | D33: 60 | E33: 60 | F33: 60 | G33: 60 | H33: 60 | I33: 60 | J33: 60 | K33: 60 | L33: 60 | M33: 60 | N33: 60 | O33: 60 | P33: =SUM(D33:O33) -> 720
C34: Telefonía móvil | D34: 45 | E34: 45 | F34: 45 | G34: 45 | H34: 45 | I34: 45 | J34: 45 | K34: 45 | L34: 45 | M34: 45 | N34: 45 | O34: 45 | P34: =SUM(D34:O34) -> 540 | Q34: Una línea por técnico y por vendedor; escala con la dotación.
C35: Infraestructura cloud base | D35: 350 | E35: 350 | F35: 350 | G35: 350 | H35: 350 | I35: 350 | J35: 350 | K35: 350 | L35: 350 | M35: 350 | N35: 350 | O35: 350 | P35: =SUM(D35:O35) -> 4200 | Q35: Capacidad mínima para operar con independencia de la cantidad de comercios activos.
C36: Licencias de software | D36: 140 | E36: 140 | F36: 140 | G36: 140 | H36: 140 | I36: 140 | J36: 140 | K36: 140 | L36: 140 | M36: 140 | N36: 140 | O36: 140 | P36: =SUM(D36:O36) -> 1680 | Q36: Herramientas de desarrollo, monitoreo y productividad.
B37: Alquiler | C37: Oficina | D37: 600 | E37: 600 | F37: 600 | G37: 600 | H37: 600 | I37: 600 | J37: 600 | K37: 600 | L37: 600 | M37: 600 | N37: 600 | O37: 600 | P37: =SUM(D37:O37) -> 7200 | Q37: En 2028 se amplía el espacio por el crecimiento de la dotación.
C38: Auditoría y certificación ISO 27001 | D38: 400 | E38: 400 | F38: 400 | G38: 400 | H38: 400 | I38: 400 | J38: 400 | K38: 400 | L38: 400 | M38: 400 | N38: 400 | O38: 400 | P38: =SUM(D38:O38) -> 4800 | Q38: Implementación durante 2027 y mantenimiento desde 2028.
B39: Honorarios | C39: Estudio Contable Externo | D39: 450 | E39: 450 | F39: 450 | G39: 450 | H39: 450 | I39: 450 | J39: 450 | K39: 450 | L39: 450 | M39: 450 | N39: 450 | O39: 450 | P39: =SUM(D39:O39) -> 5400 | Q39: Escala por tramos con la cantidad de empleados.
C40: Agencia de marketing | D40: 400 | E40: 400 | F40: 400 | G40: 400 | H40: 400 | I40: 400 | J40: 400 | K40: 400 | L40: 400 | M40: 400 | N40: 400 | O40: 400 | P40: =SUM(D40:O40) -> 4800 | Q40: Abono mensual; la pauta se imputa aparte.
B41: Publicidad online | C41: Campañas base en Meta y Google | D41: 2720 | E41: 2720 | F41: 2720 | G41: 2720 | H41: 2720 | I41: 2720 | J41: 2720 | K41: 2720 | L41: 2720 | M41: 2720 | N41: 2720 | O41: 2720 | P41: =SUM(D41:O41) -> 32640 | Q41: Pauta base permanente; las campañas de captación intensiva van en costos variables.
C42: Sitio web, SEO local y WhatsApp Business | D42: 50 | E42: 50 | F42: 50 | G42: 50 | H42: 50 | I42: 50 | J42: 50 | K42: 50 | L42: 50 | M42: 50 | N42: 50 | O42: 50 | P42: =SUM(D42:O42) -> 600
C43: Desarrollo y mantenimiento tercerizado | D43: 1200 | E43: 1200 | F43: 1200 | G43: 1200 | H43: 1200 | I43: 1200 | J43: 1200 | K43: 1200 | L43: 1200 | M43: 1200 | N43: 1200 | O43: 1200 | P43: =SUM(D43:O43) -> 14400 | Q43: Free lance, 20/40/60 h por mes según el año. Sin cargas patronales.
B44: TOTAL | D44: =SUM(D31:D43) -> 6475 | E44: =SUM(E31:E43) -> 6475 | F44: =SUM(F31:F43) -> 6475 | G44: =SUM(G31:G43) -> 6475 | H44: =SUM(H31:H43) -> 6475 | I44: =SUM(I31:I43) -> 6475 | J44: =SUM(J31:J43) -> 6475 | K44: =SUM(K31:K43) -> 6475 | ... O44: =SUM(O31:O43) -> 6475 | P44: =SUM(D44:O44) -> 77700
...

Sheet Costos variables
F1: Estructura de costos variables
B4: Evolución de la participación | H4: Costos variables - Totales
B5: 2026 | C5: 2027 | D5: 2028 | H5: 2026 | I5: 2027 | J5: 2028
B6: =Hipótesis!C24 -> 0.008 | C6: =Hipótesis!C25 -> 0.029 | D6: =Hipótesis!C26 -> 0.052 | H6: =AB32 -> 40479.8 | I6: =AB55 -> 59474.6 | J6: =AB78 -> 85346
B7: =Hipótesis!D24 -> 107520 | C7: =Hipótesis!D25 -> 389760 | D7: =Hipótesis!D26 -> 698880
H8: Costos de promoción variables - Totales
H9: 2026 | I9: 2027 | J9: 2028
H10: =SUM(AB21:AB24) -> 11265 | I10: =SUM(AB44:AB47) -> 13396 | J10: =SUM(AB67:AB70) -> 18124
B12: Costos variables - Año 2026
A13: Rubro | B13: Descripción | C13: Costo unitario | D13: Enero | F13: Febrero | H13: Marzo | J13: Abril | L13: Mayo | N13: Junio | P13: Julio | R13: Agosto | T13: Septiembre | V13: Octubre | X13: Noviembre | Z13: Diciembre | AB13: Total anual
D14: Cant. | E14: Costo | F14: Cant. | G14: Costo | H14: Cant. | I14: Costo | J14: Cant. | K14: Costo | L14: Cant. | M14: Costo | N14: Cant. | O14: Costo | P14: Cant. | Q14: Costo | R14: Cant. | S14: Costo | T14: Cant. | U14: Costo | V14: Cant. | W14: Costo | X14: Cant. | Y14: Costo | Z14: Cant. | AA14: Costo
A15: Operación | B15: Comisión del vendedor freelance por alta concretada | C15: 40 | D15: ='Proy. ventas'!E19+'Proy. ventas'!E20+'Proy. ventas'!E21 -> 0 | E15: =D15*$C15 -> 0 | F15: ='Proy. ventas'!G19+'Proy. ventas'!G20+'Proy. ventas'!G21 -> 3 | G15: =F15*$C15 -> 120 | H15: ='Proy. ventas'!I19+'Proy. ventas'!I20+'Proy. ventas'!I21 -> 4 | I15: =H15*$C15 -> 160 | J15: ='Proy. ventas'!K19+'Proy. ventas'!K20+'Proy. ventas'!K21 -> 8 | K15: =J15*$C15 -> 320 | L15: ='Proy. ventas'!M19+'Proy. ventas'!M20+'Proy. ventas'!M21 -> 14 | M15: =L15*$C15 -> 560 | N15: ='Proy. ventas'!O19+'Proy. ventas'!O20+'Proy. ventas'!O21 -> 19 | O15: =N15*$C15 -> 760 | P15: ='Proy. ventas'!Q19+'Proy. ventas'!Q20+'Proy. ventas'!Q21 -> 24 | Q15: =P15*$C15 -> 960 | R15: ='Proy. ventas'!S19+'Proy. ventas'!S20+'Proy. ventas'!S21 -> 30 | S15: =R15*$C15 -> 1200 | T15: ='Proy. ventas'!U19+'Proy. ventas'!U20+'Proy. ventas'!U21 -> 33 | U15: =T15*$C15 -> 1320 | V15: ='Proy. ventas'!W19+'Proy. ventas'!W20+'Proy. ventas'!W21 -> 41 | W15: =V15*$C15 -> 1640 | X15: ='Proy. ventas'!Y19+'Proy. ventas'!Y20+'Proy. ventas'!Y21 -> 43 | Y15: =X15*$C15 -> 1720 | Z15: ='Proy. ventas'!AA19+'Proy. ventas'!AA20+'Proy. ventas'!AA21 -> 52 | AA15: =Z15*$C15 -> 2080 | AB15: =E15+G15+I15+K15+M15+O15+Q15+S15+U15+W15+Y15+AA15 -> 10840
B16: Movilidad y viáticos de instalación | C16: 5 | D16: ='Proy. ventas'!E20+'Proy. ventas'!E21 -> 0 | E16: =D16*$C16 -> 0 | F16: ='Proy. ventas'!G20+'Proy. ventas'!G21 -> 2 | G16: =F16*$C16 -> 10 | H16: ='Proy. ventas'!I20+'Proy. ventas'!I21 -> 3 | I16: =H16*$C16 -> 15 | J16: ='Proy. ventas'!K20+'Proy. ventas'!K21 -> 6 | K16: =J16*$C16 -> 30 | L16: ='Proy. ventas'!M20+'Proy. ventas'!M21 -> 10 | M16: =L16*$C16 -> 50 | N16: ='Proy. ventas'!O20+'Proy. ventas'!O21 -> 14 | O16: =N16*$C16 -> 70 | P16: ='Proy. ventas'!Q20+'Proy. ventas'!Q21 -> 17 | Q16: =P16*$C16 -> 85 | R16: ='Proy. ventas'!S20+'Proy. ventas'!S21 -> 22 | S16: =R16*$C16 -> 110 | T16: ='Proy. ventas'!U20+'Proy. ventas'!U21 -> 24 | U16: =T16*$C16 -> 120 | V16: ='Proy. ventas'!W20+'Proy. ventas'!W21 -> 30 | W16: =V16*$C16 -> 150 | X16: ='Proy. ventas'!Y20+'Proy. ventas'!Y21 -> 31 | Y16: =X16*$C16 -> 155 | Z16: ='Proy. ventas'!AA20+'Proy. ventas'!AA21 -> 38 | AA16: =Z16*$C16 -> 190 | AB16: =E16+G16+I16+K16+M16+O16+Q16+S16+U16+W16+Y16+AA16 -> 985
B17: Consumo cloud por comercio activo | C17: 0.35 | D17: ='Proy. ventas'!E22+'Proy. ventas'!E23+'Proy. ventas'!E24 -> 0 | E17: =D17*$C17 -> 0 | F17: ='Proy. ventas'!G22+'Proy. ventas'!G23+'Proy. ventas'!G24 -> 3 | G17: =F17*$C17 -> 1.05 | H17: ='Proy. ventas'!I22+'Proy. ventas'!I23+'Proy. ventas'!I24 -> 7 | I17: =H17*$C17 -> 2.45 | J17: ='Proy. ventas'!K22+'Proy. ventas'!K23+'Proy. ventas'!K24 -> 15 | K17: =J17*$C17 -> 5.25 | L17: ='Proy. ventas'!M22+'Proy. ventas'!M23+'Proy. ventas'!M24 -> 29 | M17: =L17*$C17 -> 10.15 | N17: ='Proy. ventas'!O22+'Proy. ventas'!O23+'Proy. ventas'!O24 -> 48 | O17: =N17*$C17 -> 16.8 | P17: ='Proy. ventas'!Q22+'Proy. ventas'!Q23+'Proy. ventas'!Q24 -> 72 | Q17: =P17*$C17 -> 25.2 | R17: ='Proy. ventas'!S22+'Proy. ventas'!S23+'Proy. ventas'!S24 -> 102 | S17: =R17*$C17 -> 35.7 | T17: ='Proy. ventas'!U22+'Proy. ventas'!U23+'Proy. ventas'!U24 -> 135 | U17: =T17*$C17 -> 47.25 | V17: ='Proy. ventas'!W22+'Proy. ventas'!W23+'Proy. ventas'!W24 -> 176 | W17: =V17*$C17 -> 61.6 | X17: ='Proy. ventas'!Y22+'Proy. ventas'!Y23+'Proy. ventas'!Y24 -> 219 | Y17: =X17*$C17 -> 76.65 | Z17: ='Proy. ventas'!AA22+'Proy. ventas'!AA23+'Proy. ventas'!AA24 -> 271 | AA17: =Z17*$C17 -> 94.85 | AB17: =E17+G17+I17+K17+M17+O17+Q17+S17+U17+W17+Y17+AA17 -> 376.95
B18: Gateway de notificaciones | C18: 0.15 | D18: ='Proy. ventas'!E22+'Proy. ventas'!E23+'Proy. ventas'!E24 -> 0 | E18: =D18*$C18 -> 0 | F18: ='Proy. ventas'!G22+'Proy. ventas'!G23+'Proy. ventas'!G24 -> 3 | G18: =F18*$C18 -> 0.45 | H18: ='Proy. ventas'!I22+'Proy. ventas'!I23+'Proy. ventas'!I24 -> 7 | I18: =H18*$C18 -> 1.05 | J18: ='Proy. ventas'!K22+'Proy. ventas'!K23+'Proy. ventas'!K24 -> 15 | K18: =J18*$C18 -> 2.25 | L18: ='Proy. ventas'!M22+'Proy. ventas'!M23+'Proy. ventas'!M24 -> 29 | M18: =L18*$C18 -> 4.35 | N18: ='Proy. ventas'!O22+'Proy. ventas'!O23+'Proy. ventas'!O24 -> 48 | O18: =N18*$C18 -> 7.2 | P18: ='Proy. ventas'!Q22+'Proy. ventas'!Q23+'Proy. ventas'!Q24 -> 72 | Q18: =P18*$C18 -> 10.8 | R18: ='Proy. ventas'!S22+'Proy. ventas'!S23+'Proy. ventas'!S24 -> 102 | S18: =R18*$C18 -> 15.3 | T18: ='Proy. ventas'!U22+'Proy. ventas'!U23+'Proy. ventas'!U24 -> 135 | U18: =T18*$C18 -> 20.25 | V18: ='Proy. ventas'!W22+'Proy. ventas'!W23+'Proy. ventas'!W24 -> 176 | W18: =V18*$C18 -> 26.4 | X18: ='Proy. ventas'!Y22+'Proy. ventas'!Y23+'Proy. ventas'!Y24 -> 219 | Y18: =X18*$C18 -> 32.85 | Z18: ='Proy. ventas'!AA22+'Proy. ventas'!AA23+'Proy. ventas'!AA24 -> 271 | AA18: =Z18*$C18 -> 40.65 | AB18: =E18+G18+I18+K18+M18+O18+Q18+S18+U18+W18+Y18+AA18 -> 161.55
B19: Comisiones de medios de pago | C19: 0.9 | D19: ='Proy. ventas'!E22+'Proy. ventas'!E23+'Proy. ventas'!E24 -> 0 | E19: =D19*$C19 -> 0 | F19: ='Proy. ventas'!G22+'Proy. ventas'!G23+'Proy. ventas'!G24 -> 3 | G19: =F19*$C19 -> 2.7 | H19: ='Proy. ventas'!I22+'Proy. ventas'!I23+'Proy. ventas'!I24 -> 7 | I19: =H19*$C19 -> 6.3 | J19: ='Proy. ventas'!K22+'Proy. ventas'!K23+'Proy. ventas'!K24 -> 15 | K19: =J19*$C19 -> 13.5 | L19: ='Proy. ventas'!M22+'Proy. ventas'!M23+'Proy. ventas'!M24 -> 29 | M19: =L19*$C19 -> 26.1 | N19: ='Proy. ventas'!O22+'Proy. ventas'!O23+'Proy. ventas'!O24 -> 48 | O19: =N19*$C19 -> 43.2 | P19: ='Proy. ventas'!Q22+'Proy. ventas'!Q23+'Proy. ventas'!Q24 -> 72 | Q19: =P19*$C19 -> 64.8 | R19: ='Proy. ventas'!S22+'Proy. ventas'!S23+'Proy. ventas'!S24 -> 102 | S19: =R19*$C19 -> 91.8 | T19: ='Proy. ventas'!U22+'Proy. ventas'!U23+'Proy. ventas'!U24 -> 135 | U19: =T19*$C19 -> 121.5 | V19: ='Proy. ventas'!W22+'Proy. ventas'!W23+'Proy. ventas'!W24 -> 176 | W19: =V19*$C19 -> 158.4 | X19: ='Proy. ventas'!Y22+'Proy. ventas'!Y23+'Proy. ventas'!Y24 -> 219 | Y19: =X19*$C19 -> 197.1 | Z19: ='Proy. ventas'!AA22+'Proy. ventas'!AA23+'Proy. ventas'!AA24 -> 271 | AA19: =Z19*$C19 -> 243.9 | AB19: =E19+G19+I19+K19+M19+O19+Q19+S19+U19+W19+Y19+AA19 -> 969.3
B20: Reposición de equipamiento no recuperado | C20: 6 | D20: ='Proy. ventas'!E20+'Proy. ventas'!E21 -> 0 | E20: =D20*$C20 -> 0 | F20: ='Proy. ventas'!G20+'Proy. ventas'!G21 -> 2 | G20: =F20*$C20 -> 12 | H20: ='Proy. ventas'!I20+'Proy. ventas'!I21 -> 3 | I20: =H20*$C20 -> 18 | J20: ='Proy. ventas'!K20+'Proy. ventas'!K21 -> 6 | K20: =J20*$C20 -> 36 | L20: ='Proy. ventas'!M20+'Proy. ventas'!M21 -> 10 | M20: =L20*$C20 -> 60 | N20: ='Proy. ventas'!O20+'Proy. ventas'!O21 -> 14 | O20: =N20*$C20 -> 84 | P20: ='Proy. ventas'!Q20+'Proy. ventas'!Q21 -> 17 | Q20: =P20*$C20 -> 102 | R20: ='Proy. ventas'!S20+'Proy. ventas'!S21 -> 22 | S20: =R20*$C20 -> 132 | T20: ='Proy. ventas'!U20+'Proy. ventas'!U21 -> 24 | U20: =T20*$C20 -> 144 | V20: ='Proy. ventas'!W20+'Proy. ventas'!W21 -> 30 | W20: =V20*$C20 -> 180 | X20: ='Proy. ventas'!Y20+'Proy. ventas'!Y21 -> 31 | Y20: =X20*$C20 -> 186 | Z20: ='Proy. ventas'!AA20+'Proy. ventas'!AA21 -> 38 | AA20: =Z20*$C20 -> 228 | AB20: =E20+G20+I20+K20+M20+O20+Q20+S20+U20+W20+Y20+AA20 -> 1182
A21: Promoción | B21: Bonificación del alta - Plan Básico | C21: =Hipótesis!$C$58*0.3 -> 12 | D21: ='Proy. ventas'!E19 -> 0 | E21: =D21*$C21 -> 0 | F21: ='Proy. ventas'!G19 -> 1 | G21: =F21*$C21 -> 12 | H21: ='Proy. ventas'!I19 -> 1 | I21: =H21*$C21 -> 12 | J21: ='Proy. ventas'!K19 -> 2 | K21: =J21*$C21 -> 24 | L21: ='Proy. ventas'!M19 -> 4 | M21: =L21*$C21 -> 48 | N21: ='Proy. ventas'!O19 -> 5 | O21: =N21*$C21 -> 60 | P21: ='Proy. ventas'!Q19 -> 7 | Q21: =P21*$C21 -> 84 | R21: ='Proy. ventas'!S19 -> 8 | S21: =R21*$C21 -> 96 | T21: ='Proy. ventas'!U19 -> 9 | U21: =T21*$C21 -> 108 | V21: ='Proy. ventas'!W19 -> 11 | W21: =V21*$C21 -> 132 | X21: ='Proy. ventas'!Y19 -> 12 | Y21: =X21*$C21 -> 144 | Z21: ='Proy. ventas'!AA19 -> 14 | AA21: =Z21*$C21 -> 168 | AB21: =E21+G21+I21+K21+M21+O21+Q21+S21+U21+W21+Y21+AA21 -> 888
B22: Bonificación del alta - Plan Vidriera | C22: =Hipótesis!$C$59*0.3 -> 36 | D22: ='Proy. ventas'!E20 -> 0 | E22: =D22*$C22 -> 0 | F22: ='Proy. ventas'!G20 -> 2 | G22: =F22*$C22 -> 72 | H22: ='Proy. ventas'!I20 -> 3 | I22: =H22*$C22 -> 108 | J22: ='Proy. ventas'!K20 -> 5 | K22: =J22*$C22 -> 180 | L22: ='Proy. ventas'!M20 -> 9 | M22: =L22*$C22 -> 324 | N22: ='Proy. ventas'!O20 -> 12 | O22: =N22*$C22 -> 432 | P22: ='Proy. ventas'!Q20 -> 15 | Q22: =P22*$C22 -> 540 | R22: ='Proy. ventas'!S20 -> 19 | S22: =R22*$C22 -> 684 | T22: ='Proy. ventas'!U20 -> 21 | U22: =T22*$C22 -> 756 | V22: ='Proy. ventas'!W20 -> 26 | W22: =V22*$C22 -> 936 | X22: ='Proy. ventas'!Y20 -> 27 | Y22: =X22*$C22 -> 972 | Z22: ='Proy. ventas'!AA20 -> 33 | AA22: =Z22*$C22 -> 1188 | AB22: =E22+G22+I22+K22+M22+O22+Q22+S22+U22+W22+Y22+AA22 -> 6192
B23: Bonificación del alta - Plan Cadena | C23: =Hipótesis!$C$60*0.3 -> 135 | D23: ='Proy. ventas'!E21 -> 0 | E23: =D23*$C23 -> 0 | F23: ='Proy. ventas'!G21 -> 0 | G23: =F23*$C23 -> 0 | H23: ='Proy. ventas'!I21 -> 0 | I23: =H23*$C23 -> 0 | J23: ='Proy. ventas'!K21 -> 1 | K23: =J23*$C23 -> 135 | L23: ='Proy. ventas'!M21 -> 1 | M23: =L23*$C23 -> 135 | N23: ='Proy. ventas'!O21 -> 2 | O23: =N23*$C23 -> 270 | P23: ='Proy. ventas'!Q21 -> 2 | Q23: =P23*$C23 -> 270 | R23: ='Proy. ventas'!S21 -> 3 | S23: =R23*$C23 -> 405 | T23: ='Proy. ventas'!U21 -> 3 | U23: =T23*$C23 -> 405 | V23: ='Proy. ventas'!W21 -> 4 | W23: =V23*$C23 -> 540 | X23: ='Proy. ventas'!Y21 -> 4 | Y23: =X23*$C23 -> 540 | Z23: ='Proy. ventas'!AA21 -> 5 | AA23: =Z23*$C23 -> 675 | AB23: =E23+G23+I23+K23+M23+O23+Q23+S23+U23+W23+Y23+AA23 -> 3375
B24: Incentivo del programa de referidos | C24: 10 | D24: =ROUND(('Proy. ventas'!E19+'Proy. ventas'!E20+'Proy. ventas'!E21)*0.3,0) -> 0 | E24: =D24*$C24 -> 0 | F24: =ROUND(('Proy. ventas'!G19+'Proy. ventas'!G20+'Proy. ventas'!G21)*0.3,0) -> 1 | G24: =F24*$C24 -> 10 | H24: =ROUND(('Proy. ventas'!I19+'Proy. ventas'!I20+'Proy. ventas'!I21)*0.3,0) -> 1 | I24: =H24*$C24 -> 10 | J24: =ROUND(('Proy. ventas'!K19+'Proy. ventas'!K20+'Proy. ventas'!K21)*0.3,0) -> 2 | K24: =J24*$C24 -> 20 | L24: =ROUND(('Proy. ventas'!M19+'Proy. ventas'!M20+'Proy. ventas'!M21)*0.3,0) -> 4 | M24: =L24*$C24 -> 40 | N24: =ROUND(('Proy. ventas'!O19+'Proy. ventas'!O20+'Proy. ventas'!O21)*0.3,0) -> 6 | O24: =N24*$C24 -> 60 | P24: =ROUND(('Proy. ventas'!Q19+'Proy. ventas'!Q20+'Proy. ventas'!Q21)*0.3,0) -> 7 | Q24: =P24*$C24 -> 70 | R24: =ROUND(('Proy. ventas'!S19+'Proy. ventas'!S20+'Proy. ventas'!S21)*0.3,0) -> 9 | S24: =R24*$C24 -> 90 | T24: =ROUND(('Proy. ventas'!U19+'Proy. ventas'!U20+'Proy. ventas'!U21)*0.3,0) -> 10 | U24: =T24*$C24 -> 100 | V24: =ROUND(('Proy. ventas'!W19+'Proy. ventas'!W20+'Proy. ventas'!W21)*0.3,0) -> 12 | W24: =V24*$C24 -> 120 | X24: =ROUND(('Proy. ventas'!Y19+'Proy. ventas'!Y20+'Proy. ventas'!Y21)*0.3,0) -> 13 | Y24: =X24*$C24 -> 130 | Z24: =ROUND(('Proy. ventas'!AA19+'Proy. ventas'!AA20+'Proy. ventas'!AA21)*0.3,0) -> 16 | AA24: =Z24*$C24 -> 160 | AB24: =E24+G24+I24+K24+M24+O24+Q24+S24+U24+W24+Y24+AA24 -> 810
A25: Operación | B25: Técnico freelance de instalación y soporte (por hora, según el Anexo de capacidad) | C25: 7 | D25: ='Anexo capacidad operativa'!D87 -> 0 | E25: =D25*$C25 -> 0 | F25: ='Anexo capacidad operativa'!F87 -> 150 | G25: =F25*$C25 -> 1050 | H25: ='Anexo capacidad operativa'!H87 -> 150 | I25: =H25*$C25 -> 1050 | J25: ='Anexo capacidad operativa'!J87 -> 150 | K25: =J25*$C25 -> 1050 | L25: ='Anexo capacidad operativa'!L87 -> 150 | M25: =L25*$C25 -> 1050 | N25: ='Anexo capacidad operativa'!N87 -> 150 | O25: =N25*$C25 -> 1050 | P25: ='Anexo capacidad operativa'!P87 -> 150 | Q25: =P25*$C25 -> 1050 | R25: ='Anexo capacidad operativa'!R87 -> 150 | S25: =R25*$C25 -> 1050 | T25: ='Anexo capacidad operativa'!T87 -> 150 | U25: =T25*$C25 -> 1050 | V25: ='Anexo capacidad operativa'!V87 -> 300 | W25: =V25*$C25 -> 2100 | X25: ='Anexo capacidad operativa'!X87 -> 300 | Y25: =X25*$C25 -> 2100 | Z25: ='Anexo capacidad operativa'!Z87 -> 300 | AA25: =Z25*$C25 -> 2100 | AB25: =E25+G25+I25+K25+M25+O25+Q25+S25+U25+W25+Y25+AA25 -> 14700
B32: TOTAL | E32: =SUM(E15:E31) -> 0 | G32: =SUM(G15:G31) -> 1290.2 | I32: =SUM(I15:I31) -> 1382.8 | K32: =SUM(K15:K31) -> 1816 | M32: =SUM(M15:M31) -> 2307.6 | O32: =SUM(O15:O31) -> 2853.2 | Q32: =SUM(Q15:Q31) -> 3261.8 | S32: =SUM(S15:S31) -> 3909.8 | U32: =SUM(U15:U31) -> 4192 | W32: =SUM(W15:W31) -> 6044.4 | Y32: =SUM(Y15:Y31) -> 6253.6 | AA32: =SUM(AA15:AA31) -> 7168.4 | AB32: =SUM(AB15:AB31) -> 40479.8
B35: Costos variables - Año 2027
A36: Rubro | B36: Descripción | C36: Costo unitario | D36: Enero | F36: Febrero | H36: Marzo | J36: Abril | L36: Mayo | N36: Junio | P36: Julio | R36: Agosto | T36: Septiembre | V36: Octubre | X36: Noviembre | Z36: Diciembre | AB36: Total anual
D37: Cant. | E37: Costo | F37: Cant. | G37: Costo | H37: Cant. | I37: Costo | J37: Cant. | K37: Costo | L37: Cant. | M37: Costo | N37: Cant. | O37: Costo | P37: Cant. | Q37: Costo | R37: Cant. | S37: Costo | T37: Cant. | U37: Costo | V37: Cant. | W37: Costo | X37: Cant. | Y37: Costo | Z37: Cant. | AA37: Costo
A38: Operación | B38: Comisión del vendedor freelance por alta concretada | C38: 40 | D38: ='Proy. ventas'!E82+'Proy. ventas'!E83+'Proy. ventas'!E84 -> 22 | E38: =D38*$C38 -> 880 | F38: ='Proy. ventas'!G82+'Proy. ventas'!G83+'Proy. ventas'!G84 -> 22 | G38: =F38*$C38 -> 880 | H38: ='Proy. ventas'!I82+'Proy. ventas'!I83+'Proy. ventas'!I84 -> 25 | I38: =H38*$C38 -> 1000 | J38: ='Proy. ventas'!K82+'Proy. ventas'!K83+'Proy. ventas'!K84 -> 25 | K38: =J38*$C38 -> 1000 | L38: ='Proy. ventas'!M82+'Proy. ventas'!M83+'Proy. ventas'!M84 -> 26 | M38: =L38*$C38 -> 1040 | N38: ='Proy. ventas'!O82+'Proy. ventas'!O83+'Proy. ventas'!O84 -> 26 | O38: =N38*$C38 -> 1040 | P38: ='Proy. ventas'!Q82+'Proy. ventas'!Q83+'Proy. ventas'!Q84 -> 27 | Q38: =P38*$C38 -> 1080 | R38: ='Proy. ventas'!S82+'Proy. ventas'!S83+'Proy. ventas'!S84 -> 27 | S38: =R38*$C38 -> 1080 | T38: ='Proy. ventas'!U82+'Proy. ventas'!U83+'Proy. ventas'!U84 -> 30 | U38: =T38*$C38 -> 1200 | V38: ='Proy. ventas'!W82+'Proy. ventas'!W83+'Proy. ventas'!W84 -> 30 | W38: =V38*$C38 -> 1200 | X38: ='Proy. ventas'!Y82+'Proy. ventas'!Y83+'Proy. ventas'!Y84 -> 33 | Y38: =X38*$C38 -> 1320 | Z38: ='Proy. ventas'!AA82+'Proy. ventas'!AA83+'Proy. ventas'!AA84 -> 33 | AA38: =Z38*$C38 -> 1320 | AB38: =E38+G38+I38+K38+M38+O38+Q38+S38+U38+W38+Y38+AA38 -> 13040
B39: Movilidad y viáticos de instalación | C39: 5 | D39: ='Proy. ventas'!E83+'Proy. ventas'!E84 -> 16 | E39: =D39*$C39 -> 80 | F39: ='Proy. ventas'!G83+'Proy. ventas'!G84 -> 16 | G39: =F39*$C39 -> 80 | H39: ='Proy. ventas'!I83+'Proy. ventas'!I84 -> 18 | I39: =H39*$C39 -> 90 | J39: ='Proy. ventas'!K83+'Proy. ventas'!K84 -> 18 | K39: =J39*$C39 -> 90 | L39: ='Proy. ventas'!M83+'Proy. ventas'!M84 -> 19 | M39: =L39*$C39 -> 95 | N39: ='Proy. ventas'!O83+'Proy. ventas'!O84 -> 19 | O39: =N39*$C39 -> 95 | P39: ='Proy. ventas'!Q83+'Proy. ventas'!Q84 -> 20 | Q39: =P39*$C39 -> 100 | R39: ='Proy. ventas'!S83+'Proy. ventas'!S84 -> 20 | S39: =R39*$C39 -> 100 | T39: ='Proy. ventas'!U83+'Proy. ventas'!U84 -> 22 | U39: =T39*$C39 -> 110 | V39: ='Proy. ventas'!W83+'Proy. ventas'!W84 -> 22 | W39: =V39*$C39 -> 110 | X39: ='Proy. ventas'!Y83+'Proy. ventas'!Y84 -> 24 | Y39: =X39*$C39 -> 120 | Z39: ='Proy. ventas'!AA83+'Proy. ventas'!AA84 -> 24 | AA39: =Z39*$C39 -> 120 | AB39: =E39+G39+I39+K39+M39+O39+Q39+S39+U39+W39+Y39+AA39 -> 1190
B40: Consumo cloud por comercio activo | C40: 0.35 | D40: ='Proy. ventas'!E85+'Proy. ventas'!E86+'Proy. ventas'!E87 -> 293 | E40: =D40*$C40 -> 102.55 | F40: ='Proy. ventas'!G85+'Proy. ventas'!G86+'Proy. ventas'!G87 -> 315 | G40: =F40*$C40 -> 110.25 | H40: ='Proy. ventas'!I85+'Proy. ventas'!I86+'Proy. ventas'!I87 -> 340 | I40: =H40*$C40 -> 119 | J40: ='Proy. ventas'!K85+'Proy. ventas'!K86+'Proy. ventas'!K87 -> 365 | K40: =J40*$C40 -> 127.75 | L40: ='Proy. ventas'!M85+'Proy. ventas'!M86+'Proy. ventas'!M87 -> 391 | M40: =L40*$C40 -> 136.85 | N40: ='Proy. ventas'!O85+'Proy. ventas'!O86+'Proy. ventas'!O87 -> 417 | O40: =N40*$C40 -> 145.95 | P40: ='Proy. ventas'!Q85+'Proy. ventas'!Q86+'Proy. ventas'!Q87 -> 444 | Q40: =P40*$C40 -> 155.4 | R40: ='Proy. ventas'!S85+'Proy. ventas'!S86+'Proy. ventas'!S87 -> 471 | S40: =R40*$C40 -> 164.85 | T40: ='Proy. ventas'!U85+'Proy. ventas'!U86+'Proy. ventas'!U87 -> 501 | U40: =T40*$C40 -> 175.35 | V40: ='Proy. ventas'!W85+'Proy. ventas'!W86+'Proy. ventas'!W87 -> 531 | W40: =V40*$C40 -> 185.85 | X40: ='Proy. ventas'!Y85+'Proy. ventas'!Y86+'Proy. ventas'!Y87 -> 564 | Y40: =X40*$C40 -> 197.4 | Z40: ='Proy. ventas'!AA85+'Proy. ventas'!AA86+'Proy. ventas'!AA87 -> 597 | AA40: =Z40*$C40 -> 208.95 | AB40: =E40+G40+I40+K40+M40+O40+Q40+S40+U40+W40+Y40+AA40 -> 1830.15
B41: Gateway de notificaciones | C41: 0.15 | D41: ='Proy. ventas'!E85+'Proy. ventas'!E86+'Proy. ventas'!E87 -> 293 | E41: =D41*$C41 -> 43.95 | F41: ='Proy. ventas'!G85+'Proy. ventas'!G86+'Proy. ventas'!G87 -> 315 | G41: =F41*$C41 -> 47.25 | H41: ='Proy. ventas'!I85+'Proy. ventas'!I86+'Proy. ventas'!I87 -> 340 | I41: =H41*$C41 -> 51 | J41: ='Proy. ventas'!K85+'Proy. ventas'!K86+'Proy. ventas'!K87 -> 365 | K41: =J41*$C41 -> 54.75 | L41: ='Proy. ventas'!M85+'Proy. ventas'!M86+'Proy. ventas'!M87 -> 391 | M41: =L41*$C41 -> 58.65 | N41: ='Proy. ventas'!O85+'Proy. ventas'!O86+'Proy. ventas'!O87 -> 417 | O41: =N41*$C41 -> 62.55 | P41: ='Proy. ventas'!Q85+'Proy. ventas'!Q86+'Proy. ventas'!Q87 -> 444 | Q41: =P41*$C41 -> 66.6 | R41: ='Proy. ventas'!S85+'Proy. ventas'!S86+'Proy. ventas'!S87 -> 471 | S41: =R41*$C41 -> 70.65 | T41: ='Proy. ventas'!U85+'Proy. ventas'!U86+'Proy. ventas'!U87 -> 501 | U41: =T41*$C41 -> 75.15 | V41: ='Proy. ventas'!W85+'Proy. ventas'!W86+'Proy. ventas'!W87 -> 531 | W41: =V41*$C41 -> 79.65 | X41: ='Proy. ventas'!Y85+'Proy. ventas'!Y86+'Proy. ventas'!Y87 -> 564 | Y41: =X41*$C41 -> 84.6 | Z41: ='Proy. ventas'!AA85+'Proy. ventas'!AA86+'Proy. ventas'!AA87 -> 597 | AA41: =Z41*$C41 -> 89.55 | AB41: =E41+G41+I41+K41+M41+O41+Q41+S41+U41+W41+Y41+AA41 -> 784.35
B42: Comisiones de medios de pago | C42: 0.9 | D42: ='Proy. ventas'!E85+'Proy. ventas'!E86+'Proy. ventas'!E87 -> 293 | E42: =D42*$C42 -> 263.7 | F42: ='Proy. ventas'!G85+'Proy. ventas'!G86+'Proy. ventas'!G87 -> 315 | G42: =F42*$C42 -> 283.5 | H42: ='Proy. ventas'!I85+'Proy. ventas'!I86+'Proy. ventas'!I87 -> 340 | I42: =H42*$C42 -> 306 | J42: ='Proy. ventas'!K85+'Proy. ventas'!K86+'Proy. ventas'!K87 -> 365 | K42: =J42*$C42 -> 328.5 | L42: ='Proy. ventas'!M85+'Proy. ventas'!M86+'Proy. ventas'!M87 -> 391 | M42: =L42*$C42 -> 351.9 | N42: ='Proy. ventas'!O85+'Proy. ventas'!O86+'Proy. ventas'!O87 -> 417 | O42: =N42*$C42 -> 375.3 | P42: ='Proy. ventas'!Q85+'Proy. ventas'!Q86+'Proy. ventas'!Q87 -> 444 | Q42: =P42*$C42 -> 399.6 | R42: ='Proy. ventas'!S85+'Proy. ventas'!S86+'Proy. ventas'!S87 -> 471 | S42: =R42*$C42 -> 423.9 | T42: ='Proy. ventas'!U85+'Proy. ventas'!U86+'Proy. ventas'!U87 -> 501 | U42: =T42*$C42 -> 450.9 | V42: ='Proy. ventas'!W85+'Proy. ventas'!W86+'Proy. ventas'!W87 -> 531 | W42: =V42*$C42 -> 477.9 | X42: ='Proy. ventas'!Y85+'Proy. ventas'!Y86+'Proy. ventas'!Y87 -> 564 | Y42: =X42*$C42 -> 507.6 | Z42: ='Proy. ventas'!AA85+'Proy. ventas'!AA86+'Proy. ventas'!AA87 -> 597 | AA42: =Z42*$C42 -> 537.3 | AB42: =E42+G42+I42+K42+M42+O42+Q42+S42+U42+W42+Y42+AA42 -> 4706.1
B43: Reposición de equipamiento no recuperado | C43: 6 | D43: ='Proy. ventas'!E83+'Proy. ventas'!E84 -> 16 | E43: =D43*$C43 -> 96 | F43: ='Proy. ventas'!G83+'Proy. ventas'!G84 -> 16 | G43: =F43*$C43 -> 96 | H43: ='Proy. ventas'!I83+'Proy. ventas'!I84 -> 18 | I43: =H43*$C43 -> 108 | J43: ='Proy. ventas'!K83+'Proy. ventas'!K84 -> 18 | K43: =J43*$C43 -> 108 | L43: ='Proy. ventas'!M83+'Proy. ventas'!M84 -> 19 | M43: =L43*$C43 -> 114 | N43: ='Proy. ventas'!O83+'Proy. ventas'!O84 -> 19 | O43: =N43*$C43 -> 114 | P43: ='Proy. ventas'!Q83+'Proy. ventas'!Q84 -> 20 | Q43: =P43*$C43 -> 120 | R43: ='Proy. ventas'!S83+'Proy. ventas'!S84 -> 20 | S43: =R43*$C43 -> 120 | T43: ='Proy. ventas'!U83+'Proy. ventas'!U84 -> 22 | U43: =T43*$C43 -> 132 | V43: ='Proy. ventas'!W83+'Proy. ventas'!W84 -> 22 | W43: =V43*$C43 -> 132 | X43: ='Proy. ventas'!Y83+'Proy. ventas'!Y84 -> 24 | Y43: =X43*$C43 -> 144 | Z43: ='Proy. ventas'!AA83+'Proy. ventas'!AA84 -> 24 | AA43: =Z43*$C43 -> 144 | AB43: =E43+G43+I43+K43+M43+O43+Q43+S43+U43+W43+Y43+AA43 -> 1428
A44: Promoción | B44: Bonificación del alta - Plan Básico | C44: =Hipótesis!$C$58*0.3 -> 12 | D44: ='Proy. ventas'!E82 -> 6 | E44: =D44*$C44 -> 72 | F44: ='Proy. ventas'!G82 -> 6 | G44: =F44*$C44 -> 72 | H44: ='Proy. ventas'!I82 -> 7 | I44: =H44*$C44 -> 84 | J44: ='Proy. ventas'!K82 -> 7 | K44: =J44*$C44 -> 84 | L44: ='Proy. ventas'!M82 -> 7 | M44: =L44*$C44 -> 84 | N44: ='Proy. ventas'!O82 -> 7 | O44: =N44*$C44 -> 84 | P44: ='Proy. ventas'!Q82 -> 7 | Q44: =P44*$C44 -> 84 | R44: ='Proy. ventas'!S82 -> 7 | S44: =R44*$C44 -> 84 | T44: ='Proy. ventas'!U82 -> 8 | U44: =T44*$C44 -> 96 | V44: ='Proy. ventas'!W82 -> 8 | W44: =V44*$C44 -> 96 | X44: ='Proy. ventas'!Y82 -> 9 | Y44: =X44*$C44 -> 108 | Z44: ='Proy. ventas'!AA82 -> 9 | AA44: =Z44*$C44 -> 108 | AB44: =E44+G44+I44+K44+M44+O44+Q44+S44+U44+W44+Y44+AA44 -> 1056
B45: Bonificación del alta - Plan Vidriera | C45: =Hipótesis!$C$59*0.3 -> 36 | D45: ='Proy. ventas'!E83 -> 14 | E45: =D45*$C45 -> 504 | F45: ='Proy. ventas'!G83 -> 14 | G45: =F45*$C45 -> 504 | H45: ='Proy. ventas'!I83 -> 16 | I45: =H45*$C45 -> 576 | J45: ='Proy. ventas'!K83 -> 16 | K45: =J45*$C45 -> 576 | L45: ='Proy. ventas'!M83 -> 17 | M45: =L45*$C45 -> 612 | N45: ='Proy. ventas'!O83 -> 17 | O45: =N45*$C45 -> 612 | P45: ='Proy. ventas'!Q83 -> 18 | Q45: =P45*$C45 -> 648 | R45: ='Proy. ventas'!S83 -> 18 | S45: =R45*$C45 -> 648 | T45: ='Proy. ventas'!U83 -> 19 | U45: =T45*$C45 -> 684 | V45: ='Proy. ventas'!W83 -> 19 | W45: =V45*$C45 -> 684 | X45: ='Proy. ventas'!Y83 -> 21 | Y45: =X45*$C45 -> 756 | Z45: ='Proy. ventas'!AA83 -> 21 | AA45: =Z45*$C45 -> 756 | AB45: =E45+G45+I45+K45+M45+O45+Q45+S45+U45+W45+Y45+AA45 -> 7560
